Workbook

Sheet Sheet1
A1: Sabor | B1: Item | C1: Customer | D1: Customer Group | E1: % probabilidad catalogacion | F1: venta anual
A2: Teriyaki | B2: Teriyaki-3.78 | C2: Agnez Alimentos | D2: Mercado Libre (Distribuidor) | E2: 1
A3: Teriyaki | B3: Teriyaki-0.946 | C3: Agnez Alimentos | D3: Mercado Libre (Distribuidor) | E3: 1
A4: Teriyaki | B4: Teriyaki-0.414 | C4: Agnez Alimentos | D4: Mercado Libre (Distribuidor) | E4: 1
A5: Sriracha | B5: Sriracha-3.78 | C5: Agnez Alimentos | D5: Mercado Libre (Distribuidor) | E5: 1
A6: Sriracha | B6: Sriracha-0.946 | C6: Agnez Alimentos | D6: Mercado Libre (Distribuidor) | E6: 1
A7: Sriracha | B7: Sriracha-0.414 | C7: Agnez Alimentos | D7: Mercado Libre (Distribuidor) | E7: 1
A8: Soya | B8: Soya-3.78 | C8: Agnez Alimentos | D8: Mercado Libre (Distribuidor) | E8: 1
A9: Soya | B9: Soya-20 | C9: Agnez Alimentos | D9: Mercado Libre (Distribuidor) | E9: 1
A10: Soya | B10: Soya-0.946 | C10: Agnez Alimentos | D10: Mercado Libre (Distribuidor) | E10: 1
A11: Soya | B11: Soya-0.414 | C11: Agnez Alimentos | D11: Mercado Libre (Distribuidor) | E11: 1
A12: Ostión | B12: Ostión-3.78 | C12: Agnez Alimentos | D12: Mercado Libre (Distribuidor) | E12: 1
A13: Ostión | B13: Ostión-0.414 | C13: Agnez Alimentos | D13: Mercado Libre (Distribuidor) | E13: 1
... A30: Agridulce | B30: Agridulce-0.414 | C30: Agnez Alimentos | D30: Mercado Libre (Distribuidor) | E30: 1

Sheet 260729 costeo
A1: Salsa | B1: Name | C1: Item | D1: Item Name | E1: Desarrollar | F1: Volumen (L) | G1: Quantity | H1: Net content (kg) | I1: Densidad | J1: Total Cost (mxn) | K1: Cost per unit | L1: cost/kg | N1: MAX $/kg de competencia | O1: MIN $/kg de competencia | P1: AVG $/kg de competencia | R1: Precio público (MAX) | S1: Precio público (MIN) | T1: Precio público (AVG) | V1: Precio de venta MAX (Dist 24%) | W1: Precio de venta MIN (Dist 24%) | X1: Precio de venta AVG (Dist 24%) | Y1: Margen estimado MAX | Z1: Margen estimado MIN | AA1: Margen estimado AVG | AC1: Margen sugerido (%) | AD1: Margen propuesto (%) | AF1: Precio de venta sugerido (dist 24%) | AG1: Precio de venta (dist 24%) | AH1: Margen distribuidor | AI1: Precio público | AJ1: PP/kg | AL1: Variación vs MAX | AM1: Variación vs MIN | AN1: Variación vs AVG | AP1: Margen (pz) | AQ1: Margen (kg)
A2: Teriyaki | B2: BOM-P-0404-001 | C2: =_xlfn.TEXTJOIN("-",1,A2,F2) -> Teriyaki-3.78 | D2: (R&D) Salsa Teriyaki 3.8 L (PROJ-0291) | E2: 1 | F2: 3.78 | H2: =F2*I2 -> 4.7169811 | I2: 1.2478786 | K2: 104.47 | L2: =K2/H2 -> 22.14764 | N2: =_xlfn.MAXIFS('P-0404 Teriyaki'!$H:$H,'P-0404 Teriyaki'!$I:$I,$F2) -> 188.10573 | O2: =_xlfn.MINIFS('P-0404 Teriyaki'!$H:$H,'P-0404 Teriyaki'!$I:$I,$F2) -> 68.684211 | P2: =AVERAGEIF('P-0404 Teriyaki'!$I:$I,$F2,'P-0404 Teriyaki'!$H:$H) -> 130.93583 | R2: =N2*$H2 -> 887.29116 | S2: =O2*$H2 -> 323.98213 | T2: =P2*$H2 -> 617.62186 | V2: =R2*0.76 -> 674.34129 | W2: =S2*0.76 -> 246.22642 | X2: =T2*0.76 -> 469.39261 | Y2: =(V2-$K2)/V2 -> 0.84507845 | Z2: =(W2-$K2)/W2 -> 0.57571571 | AA2: =(X2-$K2)/X2 -> 0.77743578 | AC2: =IF(Z2>0.5,Z2,0.5) -> 0.57571571 | AD2: =(AG2-K2)/AG2 -> 0.56470833 | AF2: =K2/(1-AC2) -> 246.22642 | AG2: 240 | AH2: 0.24 | AI2: =ROUND(AG2/(1-AH2),0) -> 316 | AJ2: =AI2/H2 -> 66.992 | AL2: =($AI2-R2)/R2 -> -0.64385986 | AM2: =($AI2-S2)/S2 -> -0.024637548 | AN2: =($AI2-T2)/T2 -> -0.48836008 | AP2: =AG2-K2 -> 135.53 | AQ2: =AP2/H2 -> 28.73236
A3: Teriyaki | C3: =_xlfn.TEXTJOIN("-",1,A3,F3) -> Teriyaki-0.946 | D3: Salsa Teriyaki 946 ml | E3: 1 | F3: 0.946 | H3: =F3*I3 -> 1.1804932 | I3: 1.2478786 | K3: 37.29 | L3: =K3/H3 -> 31.588493 | N3: =_xlfn.MAXIFS('P-0404 Teriyaki'!$H:$H,'P-0404 Teriyaki'!$I:$I,$F3) -> 0 | O3: =_xlfn.MINIFS('P-0404 Teriyaki'!$H:$H,'P-0404 Teriyaki'!$I:$I,$F3) -> 0 | P3: =IFERROR(AVERAGEIF('P-0404 Teriyaki'!$I:$I,$F3,'P-0404 Teriyaki'!$H:$H),0) -> 0 | R3: =N3*$H3 -> 0 | S3: =O3*$H3 -> 0 | T3: =P3*$H3 -> 0 | V3: =R3*0.76 -> 0 | W3: =S3*0.76 -> 0 | X3: =T3*0.76 -> 0 | Y3: =IFERROR((V3-$K3)/V3,0) -> 0 | Z3: =IFERROR((W3-$K3)/W3,0) -> 0 | AA3: =IFERROR((X3-$K3)/X3,0) -> 0 | AC3: =IF(Z3>0.5,Z3,0.5) -> 0.5 | AD3: =(AG3-K3)/AG3 -> 0.533875 | AF3: =K3/(1-AC3) -> 74.58 | AG3: 80 | AH3: 0.24 | AI3: =ROUND(AG3/(1-AH3),0) -> 105 | AJ3: =AI3/H3 -> 88.945877 | AL3: =($AI3-R3)/R3 -> #DIV/0! | AM3: =($AI3-S3)/S3 -> #DIV/0! | AN3: =($AI3-T3)/T3 -> #DIV/0! | AP3: =AG3-K3 -> 42.71 | AQ3: =AP3/H3 -> 36.179795
A4: Teriyaki | C4: =_xlfn.TEXTJOIN("-",1,A4,F4) -> Teriyaki-0.414 | D4: Salsa Teriyaki 414 ml | E4: 0 | F4: 0.414 | H4: =F4*I4 -> 0.51662174 | I4: 1.2478786 | K4: 19.72 | L4: =K4/H4 -> 38.171061 | N4: =_xlfn.MAXIFS('P-0404 Teriyaki'!$H:$H,'P-0404 Teriyaki'!$I:$I,$F4) -> 540 | O4: =_xlfn.MINIFS('P-0404 Teriyaki'!$H:$H,'P-0404 Teriyaki'!$I:$I,$F4) -> 111.42857 | P4: =AVERAGEIF('P-0404 Teriyaki'!$I:$I,$F4,'P-0404 Teriyaki'!$H:$H) -> 251.92645 | R4: =N4*$H4 -> 278.97574 | S4: =O4*$H4 -> 57.566423 | T4: =P4*$H4 -> 130.15068 | V4: =R4*0.76 -> 212.02156 | W4: =S4*0.76 -> 43.750481 | X4: =T4*0.76 -> 98.914517 | Y4: =(V4-$K4)/V4 -> 0.90699059 | Z4: =(W4-$K4)/W4 -> 0.5492621 | AA4: =(X4-$K4)/X4 -> 0.80063594 | AC4: =IF(Z4>0.5,Z4,0.5) -> 0.5492621 | AD4: =(AG4-K4)/AG4 -> 0.56177778 | AF4: =K4/(1-AC4) -> 43.750481 | AG4: 45 | AH4: 0.24 | AI4: =AG4/(1-AH4) -> 59.210526 | AJ4: =AI4/H4 -> 114.61098 | AL4: =($AI4-R4)/R4 -> -0.78775744 | AM4: =($AI4-S4)/S4 -> 0.028560113 | AN4: =($AI4-T4)/T4 -> -0.54506172 | AP4: =AG4-K4 -> 25.28 | AQ4: =AP4/H4 -> 48.933287
A5: Sriracha | B5: BOM-P-0410-001 | C5: =_xlfn.TEXTJOIN("-",1,A5,F5) -> Sriracha-3.78 | D5: (R&D) Salsa Sriracha 3.8 L (PROJ-0291) | E5: 1 | F5: 3.78 | H5: =F5*I5 -> 4.5045045 | I5: 1.1916679 | K5: 114.69 | L5: =K5/H5 -> 25.46118 | N5: =_xlfn.MAXIFS('P-0410 Sriracha'!$H:$H,'P-0410 Sriracha'!$I:$I,$F5) -> 152.38095 | O5: =_xlfn.MINIFS('P-0410 Sriracha'!$H:$H,'P-0410 Sriracha'!$I:$I,$F5) -> 73.684211 | P5: =AVERAGEIF('P-0410 Sriracha'!$I:$I,$F5,'P-0410 Sriracha'!$H:$H) -> 113.03258 | R5: =N5*$H5 -> 686.40069 | S5: =O5*$H5 -> 331.91086 | T5: =P5*$H5 -> 509.15577 | V5: =R5*0.76 -> 521.66452 | W5: =S5*0.76 -> 252.25225 | X5: =T5*0.76 -> 386.95839 | Y5: =(V5-$K5)/V5 -> 0.78014606 | Z5: =(W5-$K5)/W5 -> 0.54533607 | AA5: =(X5-$K5)/X5 -> 0.70361154 | AC5: =IF(Z5>0.5,Z5,0.5) -> 0.54533607 | AD5: =(AG5-K5)/AG5 -> 0.522125 | AF5: =K5/(1-AC5) -> 252.25225 | AG5: 240 | AH5: 0.24 | AI5: =ROUND(AG5/(1-AH5),0) -> 316 | AJ5: =AI5/H5 -> 70.152 | AL5: =($AI5-R5)/R5 -> -0.5396275 | AM5: =($AI5-S5)/S5 -> -0.047937143 | AN5: =($AI5-T5)/T5 -> -0.37936479 | AP5: =AG5-K5 -> 125.31 | AQ5: =AP5/H5 -> 27.81882
A6: Sriracha | C6: =_xlfn.TEXTJOIN("-",1,A6,F6) -> Sriracha-0.946 | D6: Salsa Sriracha 946 ml | E6: 1 | F6: 0.946 | H6: =F6*I6 -> 1.1273178 | I6: 1.1916679 | K6: 39.83 | L6: =K6/H6 -> 35.331652 | N6: =_xlfn.MAXIFS('P-0410 Sriracha'!$H:$H,'P-0410 Sriracha'!$I:$I,$F6) -> 151.32409 | O6: =_xlfn.MINIFS('P-0410 Sriracha'!$H:$H,'P-0410 Sriracha'!$I:$I,$F6) -> 151.32409 | P6: =AVERAGEIF('P-0410 Sriracha'!$I:$I,$F6,'P-0410 Sriracha'!$H:$H) -> 151.32409 | R6: =N6*$H6 -> 170.59033 | S6: =O6*$H6 -> 170.59033 | T6: =P6*$H6 -> 170.59033 | V6: =R6*0.76 -> 129.64865 | W6: =S6*0.76 -> 129.64865 | X6: =T6*0.76 -> 129.64865 | Y6: =(V6-$K6)/V6 -> 0.69278509 | Z6: =(W6-$K6)/W6 -> 0.69278509 | AA6: =(X6-$K6)/X6 -> 0.69278509 | AC6: =IF(Z6>0.5,Z6,0.5) -> 0.69278509 | AD6: =(AG6-K6)/AG6 -> 0.502125 | AF6: =K6/(1-AC6) -> 129.64865 | AG6: 80 | AH6: 0.24 | AI6: =ROUND(AG6/(1-AH6),0) -> 105 | AJ6: =AI6/H6 -> 93.141438 | AL6: =($AI6-R6)/R6 -> -0.38449033 | AM6: =($AI6-S6)/S6 -> -0.38449033 | AN6: =($AI6-T6)/T6 -> -0.38449033 | AP6: =AG6-K6 -> 40.17 | AQ6: =AP6/H6 -> 35.633253
A7: Sriracha | C7: =_xlfn.TEXTJOIN("-",1,A7,F7) -> Sriracha-0.414 | D7: Salsa Sriracha 414 ml | E7: 1 | F7: 0.414 | H7: =F7*I7 -> 0.49335049 | I7: 1.1916679 | K7: 20.83 | L7: =K7/H7 -> 42.221504 | N7: =_xlfn.MAXIFS('P-0410 Sriracha'!$H:$H,'P-0410 Sriracha'!$I:$I,$F7) -> 500 | O7: =_xlfn.MINIFS('P-0410 Sriracha'!$H:$H,'P-0410 Sriracha'!$I:$I,$F7) -> 96 | P7: =AVERAGEIF('P-0410 Sriracha'!$I:$I,$F7,'P-0410 Sriracha'!$H:$H) -> 261.43584 | R7: =N7*$H7 -> 246.67525 | S7: =O7*$H7 -> 47.361647 | T7: =P7*$H7 -> 128.9795 | V7: =R7*0.76 -> 187.47319 | W7: =S7*0.76 -> 35.994852 | X7: =T7*0.76 -> 98.024421 | Y7: =(V7-$K7)/V7 -> 0.88889078 | Z7: =(W7-$K7)/W7 -> 0.42130614 | AA7: =(X7-$K7)/X7 -> 0.78750193 | AC7: =IF(Z7>0.5,Z7,0.5) -> 0.5 | AD7: =(AG7-K7)/AG7 -> 0.53711111 | AF7: =K7/(1-AC7) -> 41.66 | AG7: 45 | AH7: 0.24 | AI7: =ROUND(AG7/(1-AH7),0) -> 59 | AJ7: =AI7/H7 -> 119.59043 | AL7: =($AI7-R7)/R7 -> -0.76081913 | AM7: =($AI7-S7)/S7 -> 0.2457337 | AN7: =($AI7-T7)/T7 -> -0.54256297 | AP7: =AG7-K7 -> 24.17 | AQ7: =AP7/H7 -> 48.991539
A8: Soya | B8: BOM-P-0402-001 | C8: =_xlfn.TEXTJOIN("-",1,A8,F8) -> Soya-3.78 | D8: (R&D) Salsa de soya 3.8 L (PROJ-0291) | E8: 1 | F8: 3.78 | H8: =F8*I8 -> 4 | I8: 1.0582011 | K8: 62.8 | L8: =K8/H8 -> 15.7 | N8: =_xlfn.MAXIFS('P-0402 Soya'!$H:$H,'P-0402 Soya'!$I:$I,$F8) -> 174.07407 | O8: =_xlfn.MINIFS('P-0402 Soya'!$H:$H,'P-0402 Soya'!$I:$I,$F8) -> 22.8 | P8: =AVERAGEIF('P-0402 Soya'!$I:$I,$F8,'P-0402 Soya'!$H:$H) -> 89.761604 | R8: =N8*$H8 -> 696.2963 | S8: =O8*$H8 -> 91.2 | T8: =P8*$H8 -> 359.04642 | V8: =R8*0.76 -> 529.18519 | W8: =S8*0.76 -> 69.312 | X8: =T8*0.76 -> 272.87528 | Y8: =(V8-$K8)/V8 -> 0.88132699 | Z8: =(W8-$K8)/W8 -> 0.093951985 | AA8: =(X8-$K8)/X8 -> 0.76985823 | AC8: =IF(Z8>0.5,Z8,0.5) -> 0.5 | AD8: =(AG8-K8)/AG8 -> 0.40190476 | AF8: =K8/(1-AC8) -> 125.6 | AG8: 105 | AH8: 0.17 | AI8: =ROUND(AG8/(1-AH8),0) -> 127 | AJ8: =AI8/H8 -> 31.75 | AL8: =($AI8-R8)/R8 -> -0.81760638 | AM8: =($AI8-S8)/S8 -> 0.39254386 | AN8: =($AI8-T8)/T8 -> -0.64628529 | AP8: =AG8-K8 -> 42.2 | AQ8: =AP8/H8 -> 10.55
A9: Soya | C9: =_xlfn.TEXTJOIN("-",1,A9,F9) -> Soya-20 | D9: Salsa de soya 20 L | E9: 1 | F9: 20 | H9: =F9*I9 -> 21.164021 | I9: 1.0582011 | K9: 251.26 | L9: =K9/H9 -> 11.872035 | N9: =_xlfn.MAXIFS('P-0402 Soya'!$H:$H,'P-0402 Soya'!$I:$I,$F9) -> 24.2 | O9: =_xlfn.MINIFS('P-0402 Soya'!$H:$H,'P-0402 Soya'!$I:$I,$F9) -> 24.2 | P9: =AVERAGEIF('P-0402 Soya'!$I:$I,$F9,'P-0402 Soya'!$H:$H) -> 24.2 | R9: =N9*$H9 -> 512.16931 | S9: =O9*$H9 -> 512.16931 | T9: =P9*$H9 -> 512.16931 | V9: =R9*0.76 -> 389.24868 | W9: =S9*0.76 -> 389.24868 | X9: =T9*0.76 -> 389.24868 | Y9: =(V9-$K9)/V9 -> 0.35450005 | Z9: =(W9-$K9)/W9 -> 0.35450005 | AA9: =(X9-$K9)/X9 -> 0.35450005 | AC9: =IF(Z9>0.5,Z9,0.5) -> 0.5 | AD9: =(AG9-K9)/AG9 -> 0.4 | AF9: =K9/(1-AC9) -> 502.52 | AG9: 418.76667 | AH9: 0.17 | AI9: =ROUND(AG9/(1-AH9),0) -> 505 | AJ9: =AI9/H9 -> 23.86125 | AL9: =($AI9-R9)/R9 -> -0.013997934 | AM9: =($AI9-S9)/S9 -> -0.013997934 | AN9: =($AI9-T9)/T9 -> -0.013997934 | AP9: =AG9-K9 -> 167.50667 | AQ9: =AP9/H9 -> 7.91469
A10: Soya | C10: =_xlfn.TEXTJOIN("-",1,A10,F10) -> Soya-0.946 | D10: Salsa de soya 946 ml | E10: 0 | F10: 0.946 | H10: =F10*I10 -> 1.0010582 | I10: 1.0582011 | K10: 26.91 | L10: =K10/H10 -> 26.881554 | N10: =_xlfn.MAXIFS('P-0402 Soya'!$H:$H,'P-0402 Soya'!$I:$I,$F10) -> 166 | O10: =_xlfn.MINIFS('P-0402 Soya'!$H:$H,'P-0402 Soya'!$I:$I,$F10) -> 28 | P10: =AVERAGEIF('P-0402 Soya'!$I:$I,$F10,'P-0402 Soya'!$H:$H) -> 62.714286 | R10: =N10*$H10 -> 166.17566 | S10: =O10*$H10 -> 28.02963 | T10: =P10*$H10 -> 62.78065 | V10: =R10*0.76 -> 126.2935 | W10: =S10*0.76 -> 21.302519 | X10: =T10*0.76 -> 47.713294 | Y10: =(V10-$K10)/V10 -> 0.78692491 | Z10: =(W10-$K10)/W10 -> -0.26323092 | AA10: =(X10-$K10)/X10 -> 0.43600624 | AC10: =IF(Z10>0.5,Z10,0.5) -> 0.5 | AD10: =(AG10-K10)/AG10 -> 0.402 | AF10: =K10/(1-AC10) -> 53.82 | AG10: 45 | AH10: 0.24 | AI10: =AG10/(1-AH10) -> 59.210526 | AJ10: =AI10/H10 -> 59.147936 | AL10: =($AI10-R10)/R10 -> -0.64368713 | AM10: =($AI10-S10)/S10 -> 1.1124263 | AN10: =($AI10-T10)/T10 -> -0.056866626 | AP10: =AG10-K10 -> 18.09 | AQ10: =AP10/H10 -> 18.070877
A11: Soya | C11: =_xlfn.TEXTJOIN("-",1,A11,F11) -> Soya-0.414 | D11: Salsa de soya 414 ml | E11: 0 | F11: 0.414 | H11: =F11*I11 -> 0.43809524 | I11: 1.0582011 | K11: 15.17 | L11: =K11/H11 -> 34.627174 | N11: =_xlfn.MAXIFS('P-0402 Soya'!$H:$H,'P-0402 Soya'!$I:$I,$F11) -> 317.56757 | O11: =_xlfn.MINIFS('P-0402 Soya'!$H:$H,'P-0402 Soya'!$I:$I,$F11) -> 57.142857 | P11: =AVERAGEIF('P-0402 Soya'!$I:$I,$F11,'P-0402 Soya'!$H:$H) -> 156.26617 | R11: =N11*$H11 -> 139.12484 | S11: =O11*$H11 -> 25.034014 | T11: =P11*$H11 -> 68.459466 | V11: =R11*0.76 -> 105.73488 | W11: =S11*0.76 -> 19.02585 | X11: =T11*0.76 -> 52.029194 | Y11: =(V11-$K11)/V11 -> 0.85652795 | Z11: =(W11-$K11)/W11 -> 0.20266376 | AA11: =(X11-$K11)/X11 -> 0.70843292 | AC11: =IF(Z11>0.5,Z11,0.5) -> 0.5 | AD11: =(AG11-K11)/AG11 -> 0.49433333 | AF11: =K11/(1-AC11) -> 30.34 | AG11: 30 | AH11: 0.24 | AI11: =AG11/(1-AH11) -> 39.473684 | AJ11: =AI11/H11 -> 90.102975 | AL11: =($AI11-R11)/R11 -> -0.71627148 | AM11: =($AI11-S11)/S11 -> 0.57680206 | AN11: =($AI11-T11)/T11 -> -0.42340064 | AP11: =AG11-K11 -> 14.83 | AQ11: =AP11/H11 -> 33.851087
A12: Ostión | B12: BOM-P-0403-001 | C12: =_xlfn.TEXTJOIN("-",1,A12,F12) -> Ostión-3.78 | D12: (R&D) Salsa de ostión 3.8 L (PROJ-0291) | E12: 0 | F12: 3.78 | H12: =F12*I12 -> 4.4052863 | I12: 1.1654197 | K12: 78.33 | L12: =K12/H12 -> 17.78091 | N12: =_xlfn.MAXIFS('P-0403 - Ostion'!$H:$H,'P-0403 - Ostion'!$I:$I,$F12) -> 167.40088 | O12: =_xlfn.MINIFS('P-0403 - Ostion'!$H:$H,'P-0403 - Ostion'!$I:$I,$F12) -> 65.454545 | P12: =AVERAGEIF('P-0403 - Ostion'!$I:$I,$F12,'P-0403 - Ostion'!$H:$H) -> 108.12615 | R12: =N12*$H12 -> 737.44882 | S12: =O12*$H12 -> 288.34602 | T12: =P12*$H12 -> 476.32666 | V12: =R12*0.76 -> 560.4611 | W12: =S12*0.76 -> 219.14297 | X12: =T12*0.76 -> 362.00826 | Y12: =(V12-$K12)/V12 -> 0.86024008 | Z12: =(W12-$K12)/W12 -> 0.64256212 | AA12: =(X12-$K12)/X12 -> 0.78362372 | AC12: =IF(Z12>0.5,Z12,0.5) -> 0.64256212 | AD12: =(AG12-K12)/AG12 -> 0.60835 | AF12: =K12/(1-AC12) -> 219.14297 | AG12: 200 | AH12: 0.24 | AI12: =AG12/(1-AH12) -> 263.15789 | AJ12: =AI12/H12 -> 59.736842 | AL12: =($AI12-R12)/R12 -> -0.64315097 | AM12: =($AI12-S12)/S12 -> -0.087353801 | AN12: =($AI12-T12)/T12 -> -0.44752642 | AP12: =AG12-K12 -> 121.67 | AQ12: =AP12/H12 -> 27.61909
A13: Ostión | C13: =_xlfn.TEXTJOIN("-",1,A13,F13) -> Ostión-0.414 | D13: Salsa de Ostión 414 ml | E13: 0 | F13: 0.414 | H13: =F13*I13 -> 0.48248374 | I13: 1.1654197 | K13: 16.87 | L13: =K13/H13 -> 34.964909 | N13: =_xlfn.MAXIFS('P-0403 - Ostion'!$H:$H,'P-0403 - Ostion'!$I:$I,$F13) -> 508 | O13: =_xlfn.MINIFS('P-0403 - Ostion'!$H:$H,'P-0403 - Ostion'!$I:$I,$F13) -> 112.29167 | P13: =AVERAGEIF('P-0403 - Ostion'!$I:$I,$F13,'P-0403 - Ostion'!$H:$H) -> 236.53138 | R13: =N13*$H13 -> 245.10174 | S13: =O13*$H13 -> 54.178904 | T13: =P13*$H13 -> 114.12255 | V13: =R13*0.76 -> 186.27732 | W13: =S13*0.76 -> 41.175967 | X13: =T13*0.76 -> 86.733136 | Y13: =(V13-$K13)/V13 -> 0.9094361 | Z13: =(W13-$K13)/W13 -> 0.59029499 | AA13: =(X13-$K13)/X13 -> 0.80549533 | AC13: =IF(Z13>0.5,Z13,0.5) -> 0.59029499 | AD13: =(AG13-K13)/AG13 -> 0.57825 | AF13: =K13/(1-AC13) -> 41.175967 | AG13: 40 | AH13: 0.24 | AI13: =AG13/(1-AH13) -> 52.631579 | AJ13: =AI13/H13 -> 109.08467 | AL13: =($AI13-R13)/R13 -> -0.7852664 | AM13: =($AI13-S13)/S13 -> -0.028559541 | AN13: =($AI13-T13)/T13 -> -0.53881525 | AP13: =AG13-K13 -> 23.13 | AQ13: =AP13/H13 -> 47.939439
A14: Ostión | C14: =_xlfn.TEXTJOIN("-",1,A14,F14) -> Ostión-0.946 | D14: Salsa de Ostión 946 ml | E14: 1 | F14: 0.946 | H14: =F14*I14 -> 1.102487 | I14: 1.1654197 | K14: 30.78 | L14: =K14/H14 -> 27.918696 | N14: =_xlfn.MAXIFS('P-0403 - Ostion'!$H:$H,'P-0403 - Ostion'!$I:$I,$F14) -> 95.649351 | O14: =_xlfn.MINIFS('P-0403 - Ostion'!$H:$H,'P-0403 - Ostion'!$I:$I,$F14) -> 95.649351 | P14: =AVERAGEIF('P-0403 - Ostion'!$I:$I,$F14,'P-0403 - Ostion'!$H:$H) -> 95.649351 | R14: =N14*$H14 -> 105.45217 | S14: =O14*$H14 -> 105.45217 | T14: =P14*$H14 -> 105.45217 | V14: =R14*0.76 -> 80.143646 | W14: =S14*0.76 -> 80.143646 | X14: =T14*0.76 -> 80.143646 | Y14: =(V14-$K14)/V14 -> 0.61593961 | Z14: =(W14-$K14)/W14 -> 0.61593961 | AA14: =(X14-$K14)/X14 -> 0.61593961 | AC14: =IF(Z14>0.5,Z14,0.5) -> 0.61593961 | AD14: =(AG14-K14)/AG14 -> 0.61525 | AF14: =K14/(1-AC14) -> 80.143646 | AG14: 80 | AH14: 0.24 | AI14: =ROUND(AG14/(1-AH14),0) -> 105 | AJ14: =AI14/H14 -> 95.239218 | AL14: =($AI14-R14)/R14 -> -0.0042878795 | AM14: =($AI14-S14)/S14 -> -0.0042878795 | AN14: =($AI14-T14)/T14 -> -0.0042878795 | AP14: =AG14-K14 -> 49.22 | AQ14: =AP14/H14 -> 44.644517
A15: Mayo Chipotle | B15: BOM-P-0408-001 | C15: =_xlfn.TEXTJOIN("-",1,A15,F15) -> Mayo Chipotle-3.78 | D15: (R&D) Aderezo mayo chipotle 3.8 L (PROJ-0291) | E15: 1 | F15: 3.78 | H15: =F15*I15 -> 4.1152263 | I15: 1.0886842 | K15: 102.38 | L15: =K15/H15 -> 24.87834 | N15: =_xlfn.MAXIFS('P-0408 Mayo Chipotle'!$H:$H,'P-0408 Mayo Chipotle'!$I:$I,$F15) -> 112.5 | O15: =_xlfn.MINIFS('P-0408 Mayo Chipotle'!$H:$H,'P-0408 Mayo Chipotle'!$I:$I,$F15) -> 78.684211 | P15: =AVERAGEIF('P-0408 Mayo Chipotle'!$I:$I,$F15,'P-0408 Mayo Chipotle'!$H:$H) -> 95.592105 | R15: =N15*$H15 -> 462.96296 | S15: =O15*$H15 -> 323.80334 | T15: =P15*$H15 -> 393.38315 | V15: =R15*0.76 -> 351.85185 | W15: =S15*0.76 -> 246.09053 | X15: =T15*0.76 -> 298.97119 | Y15: =(V15-$K15)/V15 -> 0.70902526 | Z15: =(W15-$K15)/W15 -> 0.58397425 | AA15: =(X15-$K15)/X15 -> 0.65755898 | AC15: =IF(Z15>0.5,Z15,0.5) -> 0.58397425 | AD15: =(AG15-K15)/AG15 -> 0.57341667 | AF15: =K15/(1-AC15) -> 246.09053 | AG15: 240 | AH15: 0.24 | AI15: =ROUND(AG15/(1-AH15),0) -> 316 | AJ15: =AI15/H15 -> 76.788 | AL15: =($AI15-R15)/R15 -> -0.31744 | AM15: =($AI15-S15)/S15 -> -0.024098997 | AN15: =($AI15-T15)/T15 -> -0.19671191 | AP15: =AG15-K15 -> 137.62 | AQ15: =AP15/H15 -> 33.44166
A16: Mayo Chipotle | C16: =_xlfn.TEXTJOIN("-",1,A16,F16) -> Mayo Chipotle-0.946 | D16: Aderezo Mayo Chipotle 946 ml | E16: 0 | F16: 0.946 | H16: =F16*I16 -> 1.0298953 | I16: 1.0886842 | K16: 36.77 | L16: =K16/H16 -> 35.702659 | N16: =_xlfn.MAXIFS('P-0408 Mayo Chipotle'!$H:$H,'P-0408 Mayo Chipotle'!$I:$I,$F16) -> 0 | O16: =_xlfn.MINIFS('P-0408 Mayo Chipotle'!$H:$H,'P-0408 Mayo Chipotle'!$I:$I,$F16) -> 0 | P16: =IFERROR(AVERAGEIF('P-0408 Mayo Chipotle'!$I:$I,$F16,'P-0408 Mayo Chipotle'!$H:$H),0) -> 0 | R16: =N16*$H16 -> 0 | S16: =O16*$H16 -> 0 | T16: =P16*$H16 -> 0 | V16: =R16*0.76 -> 0 | W16: =S16*0.76 -> 0 | X16: =T16*0.76 -> 0 | Y16: =IFERROR((V16-$K16)/V16,0) -> 0 | Z16: =IFERROR((W16-$K16)/W16,0) -> 0 | AA16: =IFERROR((X16-$K16)/X16,0) -> 0 | AC16: =IF(Z16>0.5,Z16,0.5) -> 0.5 | AD16: =(AG16-K16)/AG16 -> 0.540375 | AF16: =K16/(1-AC16) -> 73.54 | AG16: 80 | AH16: 0.24 | AI16: =AG16/(1-AH16) -> 105.26316 | AJ16: =AI16/H16 -> 102.20763 | AL16: =($AI16-R16)/R16 -> #DIV/0! | AM16: =($AI16-S16)/S16 -> #DIV/0! | AN16: =($AI16-T16)/T16 -> #DIV/0! | AP16: =AG16-K16 -> 43.23 | AQ16: =AP16/H16 -> 41.975142
A17: Mayo Chipotle | C17: =_xlfn.TEXTJOIN("-",1,A17,F17) -> Mayo Chipotle-0.414 | D17: Aderezo Mayo Chipotle 414 ml | E17: 0 | F17: 0.414 | H17: =F17*I17 -> 0.45071527 | I17: 1.0886842 | K17: 19.49 | L17: =K17/H17 -> 43.242378 | N17: =_xlfn.MAXIFS('P-0408 Mayo Chipotle'!$H:$H,'P-0408 Mayo Chipotle'!$I:$I,$F17) -> 166.66667 | O17: =_xlfn.MINIFS('P-0408 Mayo Chipotle'!$H:$H,'P-0408 Mayo Chipotle'!$I:$I,$F17) -> 96.470588 | P17: =AVERAGEIF('P-0408 Mayo Chipotle'!$I:$I,$F17,'P-0408 Mayo Chipotle'!$H:$H) -> 126.51018 | R17: =N17*$H17 -> 75.119211 | S17: =O17*$H17 -> 43.480767 | T17: =P17*$H17 -> 57.020069 | V17: =R17*0.76 -> 57.0906 | W17: =S17*0.76 -> 33.045383 | X17: =T17*0.76 -> 43.335252 | Y17: =(V17-$K17)/V17 -> 0.6586128 | Z17: =(W17-$K17)/W17 -> 0.41020505 | AA17: =(X17-$K17)/X17 -> 0.55025069 | AC17: =IF(Z17>0.5,Z17,0.5) -> 0.5 | AD17: =(AG17-K17)/AG17 -> 0.51275 | AF17: =K17/(1-AC17) -> 38.98 | AG17: 40 | AH17: 0.24 | AI17: =AG17/(1-AH17) -> 52.631579 | AJ17: =AI17/H17 -> 116.77346 | AL17: =($AI17-R17)/R17 -> -0.29935927 | AM17: =($AI17-S17)/S17 -> 0.21045655 | AN17: =($AI17-T17)/T17 -> -0.076963953 | AP17: =AG17-K17 -> 20.51 | AQ17: =AP17/H17 -> 45.505448
A18: Anguila | C18: =_xlfn.TEXTJOIN("-",1,A18,F18) -> Anguila-3.78 | E18: 0 | F18: 3.78 | H18: =F18*I18 -> 4.71744 | I18: 1.248 | K18: 93.34 | L18: =K18/H18 -> 19.786155 | N18: =_xlfn.MAXIFS('P-0403 - Ostion'!$H:$H,'P-0403 - Ostion'!$I:$I,$F18) -> 167.40088 | O18: =_xlfn.MINIFS('P-0403 - Ostion'!$H:$H,'P-0403 - Ostion'!$I:$I,$F18) -> 65.454545 | P18: =AVERAGEIF('P-0403 - Ostion'!$I:$I,$F18,'P-0403 - Ostion'!$H:$H) -> 108.12615 | R18: =N18*$H18 -> 789.70361 | S18: =O18*$H18 -> 308.77789 | T18: =P18*$H18 -> 510.07863 | V18: =R18*0.76 -> 600.17475 | W18: =S18*0.76 -> 234.6712 | X18: =T18*0.76 -> 387.65976 | Y18: =(V18-$K18)/V18 -> 0.84447863 | Z18: =(W18-$K18)/W18 -> 0.602252 | AA18: =(X18-$K18)/X18 -> 0.75922185 | AC18: =IF(Z18>0.5,Z18,0.5) -> 0.602252 | AD18: =(AG18-K18)/AG18 -> 0.61108333 | AF18: =K18/(1-AC18) -> 234.6712 | AG18: 240 | AH18: 0.24 | AI18: =AG18/(1-AH18) -> 315.78947 | AJ18: =AI18/H18 -> 66.940856 | AL18: =($AI18-R18)/R18 -> -0.60011646 | AM18: =($AI18-S18)/S18 -> 0.022707529 | AN18: =($AI18-T18)/T18 -> -0.38090041 | AP18: =AG18-K18 -> 146.66 | AQ18: =AP18/H18 -> 31.088896
A19: Anguila | C19: =_xlfn.TEXTJOIN("-",1,A19,F19) -> Anguila-0.946 | E19: 1 | F19: 0.946 | H19: =F19*I19 -> 1.180608 | I19: 1.248 | K19: 34.51 | L19: =K19/H19 -> 29.230701 | N19: =_xlfn.MAXIFS('P-0403 - Ostion'!$H:$H,'P-0403 - Ostion'!$I:$I,$F19) -> 95.649351 | O19: =_xlfn.MINIFS('P-0403 - Ostion'!$H:$H,'P-0403 - Ostion'!$I:$I,$F19) -> 95.649351 | P19: =AVERAGEIF('P-0403 - Ostion'!$I:$I,$F19,'P-0403 - Ostion'!$H:$H) -> 95.649351 | R19: =N19*$H19 -> 112.92439 | S19: =O19*$H19 -> 112.92439 | T19: =P19*$H19 -> 112.92439 | V19: =R19*0.76 -> 85.822535 | W19: =S19*0.76 -> 85.822535 | X19: =T19*0.76 -> 85.822535 | Y19: =(V19-$K19)/V19 -> 0.59789116 | Z19: =(W19-$K19)/W19 -> 0.59789116 | AA19: =(X19-$K19)/X19 -> 0.59789116 | AC19: =IF(Z19>0.5,Z19,0.5) -> 0.59789116 | AD19: =(AG19-K19)/AG19 -> 0.568625 | AF19: =K19/(1-AC19) -> 85.822535 | AG19: 80 | AH19: 0.24 | AI19: =ROUND(AG19/(1-AH19),0) -> 105 | AJ19: =AI19/H19 -> 88.937226 | AL19: =($AI19-R19)/R19 -> -0.070174288 | AM19: =($AI19-S19)/S19 -> -0.070174288 | AN19: =($AI19-T19)/T19 -> -0.070174288 | AP19: =AG19-K19 -> 45.49 | AQ19: =AP19/H19 -> 38.530994
A20: Anguila | C20: =_xlfn.TEXTJOIN("-",1,A20,F20) -> Anguila-0.414 | E20: 0 | F20: 0.414 | H20: =F20*I20 -> 0.516672 | I20: 1.248 | K20: 18.5 | L20: =K20/H20 -> 35.806082 | N20: =_xlfn.MAXIFS('P-0403 - Ostion'!$H:$H,'P-0403 - Ostion'!$I:$I,$F20) -> 508 | O20: =_xlfn.MINIFS('P-0403 - Ostion'!$H:$H,'P-0403 - Ostion'!$I:$I,$F20) -> 112.29167 | P20: =AVERAGEIF('P-0403 - Ostion'!$I:$I,$F20,'P-0403 - Ostion'!$H:$H) -> 236.53138 | R20: =N20*$H20 -> 262.46938 | S20: =O20*$H20 -> 58.01796 | T20: =P20*$H20 -> 122.20914 | V20: =R20*0.76 -> 199.47673 | W20: =S20*0.76 -> 44.09365 | X20: =T20*0.76 -> 92.878949 | Y20: =(V20-$K20)/V20 -> 0.90725735 | Z20: =(W20-$K20)/W20 -> 0.58043845 | AA20: =(X20-$K20)/X20 -> 0.80081601 | AC20: =IF(Z20>0.5,Z20,0.5) -> 0.58043845 | AD20: =(AG20-K20)/AG20 -> 0.5375 | AF20: =K20/(1-AC20) -> 44.09365 | AG20: 40 | AH20: 0.24 | AI20: =AG20/(1-AH20) -> 52.631579 | AJ20: =AI20/H20 -> 101.86652 | AL20: =($AI20-R20)/R20 -> -0.79947535 | AM20: =($AI20-S20)/S20 -> -0.09283989 | AN20: =($AI20-T20)/T20 -> -0.56933191 | AP20: =AG20-K20 -> 21.5 | AQ20: =AP20/H20 -> 41.612474
A21: Ponzu | C21: =_xlfn.TEXTJOIN("-",1,A21,F21) -> Ponzu-20 | E21: 1 | F21: 20 | H21: =F21*I21 -> 21.16 | I21: 1.058 | K21: 295.68 | L21: =K21/H21 -> 13.973535 | N21: =_xlfn.MAXIFS('P-0402 Soya'!$H:$H,'P-0402 Soya'!$I:$I,$F21) -> 24.2 | O21: =_xlfn.MINIFS('P-0402 Soya'!$H:$H,'P-0402 Soya'!$I:$I,$F21) -> 24.2 | P21: =AVERAGEIF('P-0402 Soya'!$I:$I,$F21,'P-0402 Soya'!$H:$H) -> 24.2 | R21: =N21*$H21 -> 512.072 | S21: =O21*$H21 -> 512.072 | T21: =P21*$H21 -> 512.072 | V21: =R21*0.76 -> 389.17472 | W21: =S21*0.76 -> 389.17472 | X21: =T21*0.76 -> 389.17472 | Y21: =(V21-$K21)/V21 -> 0.24023842 | Z21: =(W21-$K21)/W21 -> 0.24023842 | AA21: =(X21-$K21)/X21 -> 0.24023842 | AC21: =IF(Z21>0.5,Z21,0.5) -> 0.5 | AD21: =(AG21-K21)/AG21 -> 0.47 | AF21: =K21/(1-AC21) -> 591.36 | AG21: 557.88679 | AH21: 0.24 | AI21: =ROUND(AG21/(1-AH21),0) -> 734 | AJ21: =AI21/H21 -> 34.688091 | AL21: =($AI21-R21)/R21 -> 0.43339218 | AM21: =($AI21-S21)/S21 -> 0.43339218 | AN21: =($AI21-T21)/T21 -> 0.43339218 | AP21: =AG21-K21 -> 262.20679 | AQ21: =AP21/H21 -> 12.391625
A22: Ponzu | C22: =_xlfn.TEXTJOIN("-",1,A22,F22) -> Ponzu-3.78 | E22: 1 | F22: 3.78 | H22: =F22*I22 -> 3.99924 | I22: 1.058 | K22: 71.24 | L22: =K22/H22 -> 17.813385 | N22: =_xlfn.MAXIFS('P-0402 Soya'!$H:$H,'P-0402 Soya'!$I:$I,$F22) -> 174.07407 | O22: =_xlfn.MINIFS('P-0402 Soya'!$H:$H,'P-0402 Soya'!$I:$I,$F22) -> 22.8 | P22: =AVERAGEIF('P-0402 Soya'!$I:$I,$F22,'P-0402 Soya'!$H:$H) -> 89.761604 | R22: =N22*$H22 -> 696.164 | S22: =O22*$H22 -> 91.182672 | T22: =P22*$H22 -> 358.9782 | V22: =R22*0.76 -> 529.08464 | W22: =S22*0.76 -> 69.298831 | X22: =T22*0.76 -> 272.82343 | Y22: =(V22-$K22)/V22 -> 0.86535236 | Z22: =(W22-$K22)/W22 -> -0.028011573 | AA22: =(X22-$K22)/X22 -> 0.73887873 | AC22: =IF(Z22>0.5,Z22,0.5) -> 0.5 | AD22: =(AG22-K22)/AG22 -> 0.4722963 | AF22: =K22/(1-AC22) -> 142.48 | AG22: 135 | AH22: 0.24 | AI22: =ROUND(AG22/(1-AH22),0) -> 178 | AJ22: =AI22/H22 -> 44.508457 | AL22: =($AI22-R22)/R22 -> -0.74431312 | AM22: =($AI22-S22)/S22 -> 0.95212529 | AN22: =($AI22-T22)/T22 -> -0.50414816 | AP22: =AG22-K22 -> 63.76 | AQ22: =AP22/H22 -> 15.943029
A23: Ponzu | C23: =_xlfn.TEXTJOIN("-",1,A23,F23) -> Ponzu-0.946 | E23: 0 | F23: 0.946 | H23: =F23*I23 -> 1.000868 | I23: 1.058 | K23: 29.01 | L23: =K23/H23 -> 28.984841 | N23: =_xlfn.MAXIFS('P-0402 Soya'!$H:$H,'P-0402 Soya'!$I:$I,$F23) -> 166 | O23: =_xlfn.MINIFS('P-0402 Soya'!$H:$H,'P-0402 Soya'!$I:$I,$F23) -> 28 | P23: =AVERAGEIF('P-0402 Soya'!$I:$I,$F23,'P-0402 Soya'!$H:$H) -> 62.714286 | R23: =N23*$H23 -> 166.14409 | S23: =O23*$H23 -> 28.024304 | T23: =P23*$H23 -> 62.768722 | V23: =R23*0.76 -> 126.26951 | W23: =S23*0.76 -> 21.298471 | X23: =T23*0.76 -> 47.704229 | Y23: =(V23-$K23)/V23 -> 0.77025332 | Z23: =(W23-$K23)/W23 -> -0.3620696 | AA23: =(X23-$K23)/X23 -> 0.39187781 | AC23: =IF(Z23>0.5,Z23,0.5) -> 0.5 | AD23: =(AG23-K23)/AG23 -> 0.4198 | AF23: =K23/(1-AC23) -> 58.02 | AG23: 50 | AH23: 0.24 | AI23: =AG23/(1-AH23) -> 65.789474 | AJ23: =AI23/H23 -> 65.732418 | AL23: =($AI23-R23)/R23 -> -0.60402158 | AM23: =($AI23-S23)/S23 -> 1.3475864 | AN23: =($AI23-T23)/T23 -> 0.048125115 | AP23: =AG23-K23 -> 20.99 | AQ23: =AP23/H23 -> 20.971796
A24: Ponzu | C24: =_xlfn.TEXTJOIN("-",1,A24,F24) -> Ponzu-0.414 | E24: 0 | F24: 0.414 | H24: =F24*I24 -> 0.438012 | I24: 1.058 | K24: 16.09 | L24: =K24/H24 -> 36.734153 | N24: =_xlfn.MAXIFS('P-0402 Soya'!$H:$H,'P-0402 Soya'!$I:$I,$F24) -> 317.56757 | O24: =_xlfn.MINIFS('P-0402 Soya'!$H:$H,'P-0402 Soya'!$I:$I,$F24) -> 57.142857 | P24: =AVERAGEIF('P-0402 Soya'!$I:$I,$F24,'P-0402 Soya'!$H:$H) -> 156.26617 | R24: =N24*$H24 -> 139.09841 | S24: =O24*$H24 -> 25.029257 | T24: =P24*$H24 -> 68.446459 | V24: =R24*0.76 -> 105.71479 | W24: =S24*0.76 -> 19.022235 | X24: =T24*0.76 -> 52.019309 | Y24: =(V24-$K24)/V24 -> 0.84779802 | Z24: =(W24-$K24)/W24 -> 0.15414778 | AA24: =(X24-$K24)/X24 -> 0.69069178 | AC24: =IF(Z24>0.5,Z24,0.5) -> 0.5 | AD24: =(AG24-K24)/AG24 -> 0.46366667 | AF24: =K24/(1-AC24) -> 32.18 | AG24: 30 | AH24: 0.24 | AI24: =AG24/(1-AH24) -> 39.473684 | AJ24: =AI24/H24 -> 90.120098 | AL24: =($AI24-R24)/R24 -> -0.71621756 | AM24: =($AI24-S24)/S24 -> 0.57710171 | AN24: =($AI24-T24)/T24 -> -0.42329107 | AP24: =AG24-K24 -> 13.91 | AQ24: =AP24/H24 -> 31.757121
A25: Samyang | C25: =_xlfn.TEXTJOIN("-",1,A25,F25) -> Samyang-3.78 | E25: 0 | F25: 3.78 | H25: =F25*I25 -> 4.50576 | I25: 1.192 | K25: 87.73 | L25: =K25/H25 -> 19.470633 | N25: =_xlfn.MAXIFS('P-0410 Sriracha'!$H:$H,'P-0410 Sriracha'!$I:$I,$F25) -> 152.38095 | O25: =_xlfn.MINIFS('P-0410 Sriracha'!$H:$H,'P-0410 Sriracha'!$I:$I,$F25) -> 73.684211 | P25: =AVERAGEIF('P-0410 Sriracha'!$I:$I,$F25,'P-0410 Sriracha'!$H:$H) -> 113.03258 | R25: =N25*$H25 -> 686.592 | S25: =O25*$H25 -> 332.00337 | T25: =P25*$H25 -> 509.29768 | V25: =R25*0.76 -> 521.80992 | W25: =S25*0.76 -> 252.32256 | X25: =T25*0.76 -> 387.06624 | Y25: =(V25-$K25)/V25 -> 0.83187364 | Z25: =(W25-$K25)/W25 -> 0.65231012 | AA25: =(X25-$K25)/X25 -> 0.77334629 | AC25: =IF(Z25>0.5,Z25,0.5) -> 0.65231012 | AD25: =(AG25-K25)/AG25 -> 0.63445833 | AF25: =K25/(1-AC25) -> 252.32256 | AG25: 240 | AH25: 0.24 | AI25: =AG25/(1-AH25) -> 315.78947 | AJ25: =AI25/H25 -> 70.085729 | AL25: =($AI25-R25)/R25 -> -0.5400624 | AM25: =($AI25-S25)/S25 -> -0.048836537 | AN25: =($AI25-T25)/T25 -> -0.37995109 | AP25: =AG25-K25 -> 152.27 | AQ25: =AP25/H25 -> 33.794521
A26: Samyang | C26: =_xlfn.TEXTJOIN("-",1,A26,F26) -> Samyang-0.946 | E26: 1 | F26: 0.946 | H26: =F26*I26 -> 1.127632 | I26: 1.192 | K26: 33.12 | L26: =K26/H26 -> 29.371284 | N26: =_xlfn.MAXIFS('P-0410 Sriracha'!$H:$H,'P-0410 Sriracha'!$I:$I,$F26) -> 151.32409 | O26: =_xlfn.MINIFS('P-0410 Sriracha'!$H:$H,'P-0410 Sriracha'!$I:$I,$F26) -> 151.32409 | P26: =AVERAGEIF('P-0410 Sriracha'!$I:$I,$F26,'P-0410 Sriracha'!$H:$H) -> 151.32409 | R26: =N26*$H26 -> 170.63788 | S26: =O26*$H26 -> 170.63788 | T26: =P26*$H26 -> 170.63788 | V26: =R26*0.76 -> 129.68479 | W26: =S26*0.76 -> 129.68479 | X26: =T26*0.76 -> 129.68479 | Y26: =(V26-$K26)/V26 -> 0.74461153 | Z26: =(W26-$K26)/W26 -> 0.74461153 | AA26: =(X26-$K26)/X26 -> 0.74461153 | AC26: =IF(Z26>0.5,Z26,0.5) -> 0.74461153 | AD26: =(AG26-K26)/AG26 -> 0.586 | AF26: =K26/(1-AC26) -> 129.68479 | AG26: 80 | AH26: 0.24 | AI26: =ROUND(AG26/(1-AH26),0) -> 105 | AJ26: =AI26/H26 -> 93.115484 | AL26: =($AI26-R26)/R26 -> -0.38466184 | AM26: =($AI26-S26)/S26 -> -0.38466184 | AN26: =($AI26-T26)/T26 -> -0.38466184 | AP26: =AG26-K26 -> 46.88 | AQ26: =AP26/H26 -> 41.573847
A27: Samyang | C27: =_xlfn.TEXTJOIN("-",1,A27,F27) -> Samyang-0.414 | E27: 0 | F27: 0.414 | H27: =F27*I27 -> 0.493488 | I27: 1.192 | K27: 17.89 | L27: =K27/H27 -> 36.252148 | N27: =_xlfn.MAXIFS('P-0410 Sriracha'!$H:$H,'P-0410 Sriracha'!$I:$I,$F27) -> 500 | O27: =_xlfn.MINIFS('P-0410 Sriracha'!$H:$H,'P-0410 Sriracha'!$I:$I,$F27) -> 96 | P27: =AVERAGEIF('P-0410 Sriracha'!$I:$I,$F27,'P-0410 Sriracha'!$H:$H) -> 261.43584 | R27: =N27*$H27 -> 246.744 | S27: =O27*$H27 -> 47.374848 | T27: =P27*$H27 -> 129.01545 | V27: =R27*0.76 -> 187.52544 | W27: =S27*0.76 -> 36.004884 | X27: =T27*0.76 -> 98.051742 | Y27: =(V27-$K27)/V27 -> 0.90459961 | Z27: =(W27-$K27)/W27 -> 0.50312297 | AA27: =(X27-$K27)/X27 -> 0.81754531 | AC27: =IF(Z27>0.5,Z27,0.5) -> 0.50312297 | AD27: =(AG27-K27)/AG27 -> 0.55275 | AF27: =K27/(1-AC27) -> 36.004884 | AG27: 40 | AH27: 0.24 | AI27: =AG27/(1-AH27) -> 52.631579 | AJ27: =AI27/H27 -> 106.6522 | AL27: =($AI27-R27)/R27 -> -0.78669561 | AM27: =($AI27-S27)/S27 -> 0.11096038 | AN27: =($AI27-T27)/T27 -> -0.59205212 | AP27: =AG27-K27 -> 22.11 | AQ27: =AP27/H27 -> 44.803521
A28: Agridulce | C28: =_xlfn.TEXTJOIN("-",1,A28,F28) -> Agridulce-3.78 | E28: 1 | F28: 3.78 | H28: =F28*I28 -> 4.71744 | I28: 1.248 | K28: 84.65 | L28: =K28/H28 -> 17.944054 | N28: =_xlfn.MAXIFS('P-0403 - Ostion'!$H:$H,'P-0403 - Ostion'!$I:$I,$F28) -> 167.40088 | O28: =_xlfn.MINIFS('P-0403 - Ostion'!$H:$H,'P-0403 - Ostion'!$I:$I,$F28) -> 65.454545 | P28: =AVERAGEIF('P-0403 - Ostion'!$I:$I,$F28,'P-0403 - Ostion'!$H:$H) -> 108.12615 | R28: =N28*$H28 -> 789.70361 | S28: =O28*$H28 -> 308.77789 | T28: =P28*$H28 -> 510.07863 | V28: =R28*0.76 -> 600.17475 | W28: =S28*0.76 -> 234.6712 | X28: =T28*0.76 -> 387.65976 | Y28: =(V28-$K28)/V28 -> 0.85895774 | Z28: =(W28-$K28)/W28 -> 0.63928253 | AA28: =(X28-$K28)/X28 -> 0.78163841 | AC28: =IF(Z28>0.5,Z28,0.5) -> 0.63928253 | AD28: =(AG28-K28)/AG28 -> 0.64729167 | AF28: =K28/(1-AC28) -> 234.6712 | AG28: 240 | AH28: 0.24 | AI28: =ROUND(AG28/(1-AH28),0) -> 316 | AJ28: =AI28/H28 -> 66.985484 | AL28: =($AI28-R28)/R28 -> -0.59984987 | AM28: =($AI28-S28)/S28 -> 0.023389334 | AN28: =($AI28-T28)/T28 -> -0.38048767 | AP28: =AG28-K28 -> 155.35 | AQ28: =AP28/H28 -> 32.930996
A29: Agridulce | C29: =_xlfn.TEXTJOIN("-",1,A29,F29) -> Agridulce-0.946 | E29: 0 | F29: 0.946 | H29: =F29*I29 -> 1.180608 | I29: 1.248 | K29: 32.35 | L29: =K29/H29 -> 27.401136 | N29: =_xlfn.MAXIFS('P-0403 - Ostion'!$H:$H,'P-0403 - Ostion'!$I:$I,$F29) -> 95.649351 | O29: =_xlfn.MINIFS('P-0403 - Ostion'!$H:$H,'P-0403 - Ostion'!$I:$I,$F29) -> 95.649351 | P29: =AVERAGEIF('P-0403 - Ostion'!$I:$I,$F29,'P-0403 - Ostion'!$H:$H) -> 95.649351 | R29: =N29*$H29 -> 112.92439 | S29: =O29*$H29 -> 112.92439 | T29: =P29*$H29 -> 112.92439 | V29: =R29*0.76 -> 85.822535 | W29: =S29*0.76 -> 85.822535 | X29: =T29*0.76 -> 85.822535 | Y29: =(V29-$K29)/V29 -> 0.62305938 | Z29: =(W29-$K29)/W29 -> 0.62305938 | AA29: =(X29-$K29)/X29 -> 0.62305938 | AC29: =IF(Z29>0.5,Z29,0.5) -> 0.62305938 | AD29: =(AG29-K29)/AG29 -> 0.56866667 | AF29: =K29/(1-AC29) -> 85.822535 | AG29: 75 | AH29: 0.24 | AI29: =AG29/(1-AH29) -> 98.684211 | AJ29: =AI29/H29 -> 83.587618 | AL29: =($AI29-R29)/R29 -> -0.12610365 | AM29: =($AI29-S29)/S29 -> -0.12610365 | AN29: =($AI29-T29)/T29 -> -0.12610365 | AP29: =AG29-K29 -> 42.65 | AQ29: =AP29/H29 -> 36.125454
A30: Agridulce | C30: =_xlfn.TEXTJOIN("-",1,A30,F30) -> Agridulce-0.414 | E30: 0 | F30: 0.414 | H30: =F30*I30 -> 0.516672 | I30: 1.248 | K30: 17.56 | L30: =K30/H30 -> 33.986746 | N30: =_xlfn.MAXIFS('P-0403 - Ostion'!$H:$H,'P-0403 - Ostion'!$I:$I,$F30) -> 508 | O30: =_xlfn.MINIFS('P-0403 - Ostion'!$H:$H,'P-0403 - Ostion'!$I:$I,$F30) -> 112.29167 | P30: =AVERAGEIF('P-0403 - Ostion'!$I:$I,$F30,'P-0403 - Ostion'!$H:$H) -> 236.53138 | R30: =N30*$H30 -> 262.46938 | S30: =O30*$H30 -> 58.01796 | T30: =P30*$H30 -> 122.20914 | V30: =R30*0.76 -> 199.47673 | W30: =S30*0.76 -> 44.09365 | X30: =T30*0.76 -> 92.878949 | Y30: =(V30-$K30)/V30 -> 0.91196968 | Z30: =(W30-$K30)/W30 -> 0.60175671 | AA30: =(X30-$K30)/X30 -> 0.81093671 | AC30: =IF(Z30>0.5,Z30,0.5) -> 0.60175671 | AD30: =(AG30-K30)/AG30 -> 0.561 | AF30: =K30/(1-AC30) -> 44.09365 | AG30: 40 | AH30: 0.24 | AI30: =AG30/(1-AH30) -> 52.631579 | AJ30: =AI30/H30 -> 101.86652 | AL30: =($AI30-R30)/R30 -> -0.79947535 | AM30: =($AI30-S30)/S30 -> -0.09283989 | AN30: =($AI30-T30)/T30 -> -0.56933191 | AP30: =AG30-K30 -> 22.44 | AQ30: =AP30/H30 -> 43.43181

Sheet 260324 costeo
A1: Salsa | B1: Name | C1: Item | D1: Item Name | E1: Volumen (L) | F1: Quantity | G1: Net content (kg) | H1: Densidad | I1: Total Cost (mxn) | J1: Cost per unit | K1: cost/kg | M1: MAX $/kg de competencia | N1: MIN $/kg de competencia | O1: AVG $/kg de competencia | Q1: Precio público (MAX) | R1: Precio público (MIN) | S1: Precio público (AVG) | U1: Precio de venta MAX (Dist 24%) | V1: Precio de venta MIN (Dist 24%) | W1: Precio de venta AVG (Dist 24%) | X1: Margen estimado MAX | Y1: Margen estimado MIN | Z1: Margen estimado AVG | AB1: Margen sugerido (%) | AC1: Margen propuesto (%) | AE1: Precio de venta sugerido | AF1: Margen distribuidor | AG1: Precio público | AH1: PP/kg | AJ1: Variación vs MAX | AK1: Variación vs MIN | AL1: Variación vs AVG | AN1: Margen (pz) | AO1: Margen (kg)
A2: Teriyaki | B2: BOM-P-0404-001 | C2: =_xlfn.TEXTJOIN("-",1,A2,E2) -> Teriyaki-3.78 | D2: (R&D) Salsa Teriyaki 3.8 L (PROJ-0291) | E2: 3.78 | F2: 212 | G2: =1000/F2 -> 4.7169811 | H2: 1.2478786 | I2: 20767.51 | J2: =I2/F2 -> 97.959952 | K2: =J2/G2 -> 20.76751 | M2: =_xlfn.MAXIFS('P-0404 Teriyaki'!$H:$H,'P-0404 Teriyaki'!$I:$I,$E2) -> 188.10573 | N2: =_xlfn.MINIFS('P-0404 Teriyaki'!$H:$H,'P-0404 Teriyaki'!$I:$I,$E2) -> 68.684211 | O2: =AVERAGEIF('P-0404 Teriyaki'!$I:$I,$E2,'P-0404 Teriyaki'!$H:$H) -> 130.93583 | Q2: =M2*$G2 -> 887.29116 | R2: =N2*$G2 -> 323.98213 | S2: =O2*$G2 -> 617.62186 | U2: =Q2*0.76 -> 674.34129 | V2: =R2*0.76 -> 246.22642 | W2: =S2*0.76 -> 469.39261 | X2: =(U2-$J2)/U2 -> 0.85473238 | Y2: =(V2-$J2)/V2 -> 0.60215498 | Z2: =(W2-$J2)/W2 -> 0.79130487 | AB2: =IF(Y2>0.5,Y2,0.5) -> 0.60215498 | AC2: 0.60215498 | AE2: =J2/(1-AC2) -> 246.22642 | AF2: 0.24 | AG2: =AE2/(1-AF2) -> 323.98213 | AH2: =AG2/G2 -> 68.684211 | AJ2: =($AG2-Q2)/Q2 -> -0.6348638 | AK2: =($AG2-R2)/R2 -> 0 | AL2: =($AG2-S2)/S2 -> -0.47543611 | AN2: =AE2-J2 -> 148.26646 | AO2: =AN2/G2 -> 31.43249
A3: Teriyaki | C3: =_xlfn.TEXTJOIN("-",1,A3,E3) -> Teriyaki-0.946 | D3: Salsa Teriyaki 946 ml | E3: 0.946 | F3: =ROUND(1000/G3,0) -> 847 | G3: =E3*H3 -> 1.1804932 | H3: 1.2478786 | I3: 28326 | J3: =I3/F3 -> 33.442739 | K3: =J3/G3 -> 28.329464 | M3: =_xlfn.MAXIFS('P-0404 Teriyaki'!$H:$H,'P-0404 Teriyaki'!$I:$I,$E3) -> 0 | N3: =_xlfn.MINIFS('P-0404 Teriyaki'!$H:$H,'P-0404 Teriyaki'!$I:$I,$E3) -> 0 | O3: =IFERROR(AVERAGEIF('P-0404 Teriyaki'!$I:$I,$E3,'P-0404 Teriyaki'!$H:$H),0) -> 0 | Q3: =M3*$G3 -> 0 | R3: =N3*$G3 -> 0 | S3: =O3*$G3 -> 0 | U3: =Q3*0.76 -> 0 | V3: =R3*0.76 -> 0 | W3: =S3*0.76 -> 0 | X3: =IFERROR((U3-$J3)/U3,0) -> 0 | Y3: =IFERROR((V3-$J3)/V3,0) -> 0 | Z3: =IFERROR((W3-$J3)/W3,0) -> 0 | AB3: =IF(Y3>0.5,Y3,0.5) -> 0.5 | AC3: 0.5 | AE3: =J3/(1-AC3) -> 66.885478 | AF3: 0.24 | AG3: =AE3/(1-AF3) -> 88.007208 | AH3: =AG3/G3 -> 74.551222 | AJ3: =($AG3-Q3)/Q3 -> #DIV/0! | AK3: =($AG3-R3)/R3 -> #DIV/0! | AL3: =($AG3-S3)/S3 -> #DIV/0! | AN3: =AE3-J3 -> 33.442739 | AO3: =AN3/G3 -> 28.329464
A4: Teriyaki | C4: =_xlfn.TEXTJOIN("-",1,A4,E4) -> Teriyaki-0.414 | D4: Salsa Teriyaki 414 ml | E4: 0.414 | F4: =ROUND(1000/G4,0) -> 1936 | G4: =E4*H4 -> 0.51662174 | H4: 1.2478786 | I4: 34710 | J4: =I4/F4 -> 17.928719 | K4: =J4/G4 -> 34.703764 | M4: =_xlfn.MAXIFS('P-0404 Teriyaki'!$H:$H,'P-0404 Teriyaki'!$I:$I,$E4) -> 540 | N4: =_xlfn.MINIFS('P-0404 Teriyaki'!$H:$H,'P-0404 Teriyaki'!$I:$I,$E4) -> 111.42857 | O4: =AVERAGEIF('P-0404 Teriyaki'!$I:$I,$E4,'P-0404 Teriyaki'!$H:$H) -> 251.92645 | Q4: =M4*$G4 -> 278.97574 | R4: =N4*$G4 -> 57.566423 | S4: =O4*$G4 -> 130.15068 | U4: =Q4*0.76 -> 212.02156 | V4: =R4*0.76 -> 43.750481 | W4: =S4*0.76 -> 98.914517 | X4: =(U4-$J4)/U4 -> 0.91543917 | Y4: =(V4-$J4)/V4 -> 0.59020522 | Z4: =(W4-$J4)/W4 -> 0.81874532 | AB4: =IF(Y4>0.5,Y4,0.5) -> 0.59020522 | AC4: 0.59020522 | AE4: =J4/(1-AC4) -> 43.750481 | AF4: 0.24 | AG4: =AE4/(1-AF4) -> 57.566423 | AH4: =AG4/G4 -> 111.42857 | AJ4: =($AG4-Q4)/Q4 -> -0.79365079 | AK4: =($AG4-R4)/R4 -> 0 | AL4: =($AG4-S4)/S4 -> -0.55769403 | AN4: =AE4-J4 -> 25.821762 | AO4: =AN4/G4 -> 49.98195
A5: Sriracha | B5: BOM-P-0410-001 | C5: =_xlfn.TEXTJOIN("-",1,A5,E5) -> Sriracha-3.78 | D5: (R&D) Salsa Sriracha 3.8 L (PROJ-0291) | E5: 3.78 | F5: 222 | G5: =E5*H5 -> 4.5045045 | H5: 1.1916679 | I5: 20967.297 | J5: =I5/F5 -> 94.447283 | K5: =J5/G5 -> 20.967297 | M5: =_xlfn.MAXIFS('P-0410 Sriracha'!$H:$H,'P-0410 Sriracha'!$I:$I,$E5) -> 152.38095 | N5: =_xlfn.MINIFS('P-0410 Sriracha'!$H:$H,'P-0410 Sriracha'!$I:$I,$E5) -> 73.684211 | O5: =AVERAGEIF('P-0410 Sriracha'!$I:$I,$E5,'P-0410 Sriracha'!$H:$H) -> 113.03258 | Q5: =M5*$G5 -> 686.40069 | R5: =N5*$G5 -> 331.91086 | S5: =O5*$G5 -> 509.15577 | U5: =Q5*0.76 -> 521.66452 | V5: =R5*0.76 -> 252.25225 | W5: =S5*0.76 -> 386.95839 | X5: =(U5-$J5)/U5 -> 0.81895015 | Y5: =(V5-$J5)/V5 -> 0.62558399 | Z5: =(W5-$J5)/W5 -> 0.75592393 | AB5: =IF(Y5>0.5,Y5,0.5) -> 0.62558399 | AC5: 0.62558399 | AE5: =J5/(1-AC5) -> 252.25225 | AF5: 0.24 | AG5: =AE5/(1-AF5) -> 331.91086 | AH5: =AG5/G5 -> 73.684211 | AJ5: =($AG5-Q5)/Q5 -> -0.51644737 | AK5: =($AG5-R5)/R5 -> 0 | AL5: =($AG5-S5)/S5 -> -0.3481153 | AN5: =AE5-J5 -> 157.80497 | AO5: =AN5/G5 -> 35.032703
A6: Sriracha | C6: =_xlfn.TEXTJOIN("-",1,A6,E6) -> Sriracha-0.946 | D6: Salsa Sriracha 946 ml | E6: 0.946 | F6: =ROUND(1000/G6,0) -> 887 | G6: =E6*H6 -> 1.1273178 | H6: 1.1916679 | I6: 27472 | J6: =I6/F6 -> 30.971815 | K6: =J6/G6 -> 27.473899 | M6: =_xlfn.MAXIFS('P-0410 Sriracha'!$H:$H,'P-0410 Sriracha'!$I:$I,$E6) -> 151.32409 | N6: =_xlfn.MINIFS('P-0410 Sriracha'!$H:$H,'P-0410 Sriracha'!$I:$I,$E6) -> 151.32409 | O6: =AVERAGEIF('P-0410 Sriracha'!$I:$I,$E6,'P-0410 Sriracha'!$H:$H) -> 151.32409 | Q6: =M6*$G6 -> 170.59033 | R6: =N6*$G6 -> 170.59033 | S6: =O6*$G6 -> 170.59033 | U6: =Q6*0.76 -> 129.64865 | V6: =R6*0.76 -> 129.64865 | W6: =S6*0.76 -> 129.64865 | X6: =(U6-$J6)/U6 -> 0.76110963 | Y6: =(V6-$J6)/V6 -> 0.76110963 | Z6: =(W6-$J6)/W6 -> 0.76110963 | AB6: =IF(Y6>0.5,Y6,0.5) -> 0.76110963 | AC6: 0.6 | AE6: =J6/(1-AC6) -> 77.429538 | AF6: 0.24 | AG6: =AE6/(1-AF6) -> 101.88097 | AH6: =AG6/G6 -> 90.374667 | AJ6: =($AG6-Q6)/Q6 -> -0.40277407 | AK6: =($AG6-R6)/R6 -> -0.40277407 | AL6: =($AG6-S6)/S6 -> -0.40277407 | AN6: =AE6-J6 -> 46.457723 | AO6: =AN6/G6 -> 41.210848
A7: Sriracha | C7: =_xlfn.TEXTJOIN("-",1,A7,E7) -> Sriracha-0.414 | D7: Salsa Sriracha 414 ml | E7: 0.414 | F7: =ROUND(1000/G7,0) -> 2027 | G7: =E7*H7 -> 0.49335049 | H7: 1.1916679 | I7: 35571 | J7: =I7/F7 -> 17.548594 | K7: =J7/G7 -> 35.570237 | M7: =_xlfn.MAXIFS('P-0410 Sriracha'!$H:$H,'P-0410 Sriracha'!$I:$I,$E7) -> 500 | N7: =_xlfn.MINIFS('P-0410 Sriracha'!$H:$H,'P-0410 Sriracha'!$I:$I,$E7) -> 96 | O7: =AVERAGEIF('P-0410 Sriracha'!$I:$I,$E7,'P-0410 Sriracha'!$H:$H) -> 261.43584 | Q7: =M7*$G7 -> 246.67525 | R7: =N7*$G7 -> 47.361647 | S7: =O7*$G7 -> 128.9795 | U7: =Q7*0.76 -> 187.47319 | V7: =R7*0.76 -> 35.994852 | W7: =S7*0.76 -> 98.024421 | X7: =(U7-$J7)/U7 -> 0.90639411 | Y7: =(V7-$J7)/V7 -> 0.51246934 | Z7: =(W7-$J7)/W7 -> 0.82097733 | AB7: =IF(Y7>0.5,Y7,0.5) -> 0.51246934 | AC7: 0.6 | AE7: =J7/(1-AC7) -> 43.871485 | AF7: 0.24 | AG7: =AE7/(1-AF7) -> 57.725638 | AH7: =AG7/G7 -> 117.00736 | AJ7: =($AG7-Q7)/Q7 -> -0.76598528 | AK7: =($AG7-R7)/R7 -> 0.21882665 | AL7: =($AG7-S7)/S7 -> -0.55244331 | AN7: =AE7-J7 -> 26.322891 | AO7: =AN7/G7 -> 53.355356
A8: Soya | B8: BOM-P-0402-001 | C8: =_xlfn.TEXTJOIN("-",1,A8,E8) -> Soya-3.78 | D8: (R&D) Salsa de soya 3.8 L (PROJ-0291) | E8: 3.78 | F8: 250 | G8: =E8*H8 -> 4 | H8: 1.0582011 | I8: 14286.393 | J8: =I8/F8 -> 57.145572 | K8: =J8/G8 -> 14.286393 | M8: =_xlfn.MAXIFS('P-0402 Soya'!$H:$H,'P-0402 Soya'!$I:$I,$E8) -> 174.07407 | N8: =_xlfn.MINIFS('P-0402 Soya'!$H:$H,'P-0402 Soya'!$I:$I,$E8) -> 22.8 | O8: =AVERAGEIF('P-0402 Soya'!$I:$I,$E8,'P-0402 Soya'!$H:$H) -> 89.761604 | Q8: =M8*$G8 -> 696.2963 | R8: =N8*$G8 -> 91.2 | S8: =O8*$G8 -> 359.04642 | U8: =Q8*0.76 -> 529.18519 | V8: =R8*0.76 -> 69.312 | W8: =S8*0.76 -> 272.87528 | X8: =(U8-$J8)/U8 -> 0.89201215 | Y8: =(V8-$J8)/V8 -> 0.17553134 | Z8: =(W8-$J8)/W8 -> 0.79057989 | AB8: =IF(Y8>0.5,Y8,0.5) -> 0.5 | AC8: 0.4 | AE8: =J8/(1-AC8) -> 95.242619 | AF8: 0.17 | AG8: =AE8/(1-AF8) -> 114.75014 | AH8: =AG8/G8 -> 28.687536 | AJ8: =($AG8-Q8)/Q8 -> -0.83519926 | AK8: =($AG8-R8)/R8 -> 0.25822526 | AL8: =($AG8-S8)/S8 -> -0.68040304 | AN8: =AE8-J8 -> 38.097048 | AO8: =AN8/G8 -> 9.5242619
A9: Soya | C9: =_xlfn.TEXTJOIN("-",1,A9,E9) -> Soya-20 | D9: Salsa de soya 20 L | E9: 20 | F9: =ROUND(1000/G9,0) -> 47 | G9: =E9*H9 -> 21.164021 | H9: 1.0582011 | I9: 12382.71 | J9: =I9/F9 -> 263.46191 | K9: =J9/G9 -> 12.448575 | M9: =_xlfn.MAXIFS('P-0402 Soya'!$H:$H,'P-0402 Soya'!$I:$I,$E9) -> 24.2 | N9: =_xlfn.MINIFS('P-0402 Soya'!$H:$H,'P-0402 Soya'!$I:$I,$E9) -> 24.2 | O9: =AVERAGEIF('P-0402 Soya'!$I:$I,$E9,'P-0402 Soya'!$H:$H) -> 24.2 | Q9: =M9*$G9 -> 512.16931 | R9: =N9*$G9 -> 512.16931 | S9: =O9*$G9 -> 512.16931 | U9: =Q9*0.76 -> 389.24868 | V9: =R9*0.76 -> 389.24868 | W9: =S9*0.76 -> 389.24868 | X9: =(U9-$J9)/U9 -> 0.3231527 | Y9: =(V9-$J9)/V9 -> 0.3231527 | Z9: =(W9-$J9)/W9 -> 0.3231527 | AB9: =IF(Y9>0.5,Y9,0.5) -> 0.5 | AC9: 0.4 | AE9: =J9/(1-AC9) -> 439.10319 | AF9: 0.17 | AG9: =AE9/(1-AF9) -> 529.03999 | AH9: =AG9/G9 -> 24.99714 | AJ9: =($AG9-Q9)/Q9 -> 0.032939649 | AK9: =($AG9-R9)/R9 -> 0.032939649 | AL9: =($AG9-S9)/S9 -> 0.032939649 | AN9: =AE9-J9 -> 175.64128 | AO9: =AN9/G9 -> 8.2990503
A10: Soya | C10: =_xlfn.TEXTJOIN("-",1,A10,E10) -> Soya-0.946 | D10: Salsa de soya 946 ml | E10: 0.946 | F10: =ROUND(1000/G10,0) -> 999 | G10: =E10*H10 -> 1.0010582 | H10: 1.0582011 | I10: 21362 | J10: =I10/F10 -> 21.383383 | K10: =J10/G10 -> 21.360779 | M10: =_xlfn.MAXIFS('P-0402 Soya'!$H:$H,'P-0402 Soya'!$I:$I,$E10) -> 166 | N10: =_xlfn.MINIFS('P-0402 Soya'!$H:$H,'P-0402 Soya'!$I:$I,$E10) -> 28 | O10: =AVERAGEIF('P-0402 Soya'!$I:$I,$E10,'P-0402 Soya'!$H:$H) -> 62.714286 | Q10: =M10*$G10 -> 166.17566 | R10: =N10*$G10 -> 28.02963 | S10: =O10*$G10 -> 62.78065 | U10: =Q10*0.76 -> 126.2935 | V10: =R10*0.76 -> 21.302519 | W10: =S10*0.76 -> 47.713294 | X10: =(U10-$J10)/U10 -> 0.83068501 | Y10: =(V10-$J10)/V10 -> -0.0037960237 | Z10: =(W10-$J10)/W10 -> 0.55183594 | AB10: =IF(Y10>0.5,Y10,0.5) -> 0.5 | AC10: 0.5 | AE10: =J10/(1-AC10) -> 42.766767 | AF10: 0.24 | AG10: =AE10/(1-AF10) -> 56.272062 | AH10: =AG10/G10 -> 56.212577 | AJ10: =($AG10-Q10)/Q10 -> -0.66137002 | AK10: =($AG10-R10)/R10 -> 1.007592 | AL10: =($AG10-S10)/S10 -> -0.10367189 | AN10: =AE10-J10 -> 21.383383 | AO10: =AN10/G10 -> 21.360779
A11: Soya | C11: =_xlfn.TEXTJOIN("-",1,A11,E11) -> Soya-0.414 | D11: Salsa de soya 414 ml | E11: 0.414 | F11: =ROUND(1000/G11,0) -> 2283 | G11: =E11*H11 -> 0.43809524 | H11: 1.0582011 | I11: 30483 | J11: =I11/F11 -> 13.352168 | K11: =J11/G11 -> 30.477775 | M11: =_xlfn.MAXIFS('P-0402 Soya'!$H:$H,'P-0402 Soya'!$I:$I,$E11) -> 317.56757 | N11: =_xlfn.MINIFS('P-0402 Soya'!$H:$H,'P-0402 Soya'!$I:$I,$E11) -> 57.142857 | O11: =AVERAGEIF('P-0402 Soya'!$I:$I,$E11,'P-0402 Soya'!$H:$H) -> 156.26617 | Q11: =M11*$G11 -> 139.12484 | R11: =N11*$G11 -> 25.034014 | S11: =O11*$G11 -> 68.459466 | U11: =Q11*0.76 -> 105.73488 | V11: =R11*0.76 -> 19.02585 | W11: =S11*0.76 -> 52.029194 | X11: =(U11-$J11)/U11 -> 0.8737203 | Y11: =(V11-$J11)/V11 -> 0.29820912 | Z11: =(W11-$J11)/W11 -> 0.74337161 | AB11: =IF(Y11>0.5,Y11,0.5) -> 0.5 | AC11: 0.5 | AE11: =J11/(1-AC11) -> 26.704336 | AF11: 0.24 | AG11: =AE11/(1-AF11) -> 35.137285 | AH11: =AG11/G11 -> 80.204672 | AJ11: =($AG11-Q11)/Q11 -> -0.74744061 | AK11: =($AG11-R11)/R11 -> 0.40358175 | AL11: =($AG11-S11)/S11 -> -0.48674322 | AN11: =AE11-J11 -> 13.352168 | AO11: =AN11/G11 -> 30.477775
A12: Ostión | B12: BOM-P-0403-001 | C12: =_xlfn.TEXTJOIN("-",1,A12,E12) -> Ostión-3.78 | D12: (R&D) Salsa de ostión 3.8 L (PROJ-0291) | E12: 3.78 | F12: 227 | G12: =E12*H12 -> 4.4052863 | H12: 1.1654197 | I12: 21735.404 | J12: =I12/F12 -> 95.750678 | K12: =J12/G12 -> 21.735404 | M12: =_xlfn.MAXIFS('P-0403 - Ostion'!$H:$H,'P-0403 - Ostion'!$I:$I,$E12) -> 167.40088 | N12: =_xlfn.MINIFS('P-0403 - Ostion'!$H:$H,'P-0403 - Ostion'!$I:$I,$E12) -> 65.454545 | O12: =AVERAGEIF('P-0403 - Ostion'!$I:$I,$E12,'P-0403 - Ostion'!$H:$H) -> 108.12615 | Q12: =M12*$G12 -> 737.44882 | R12: =N12*$G12 -> 288.34602 | S12: =O12*$G12 -> 476.32666 | U12: =Q12*0.76 -> 560.4611 | V12: =R12*0.76 -> 219.14297 | W12: =S12*0.76 -> 362.00826 | X12: =(U12-$J12)/U12 -> 0.82915732 | Y12: =(V12-$J12)/V12 -> 0.56306754 | Z12: =(W12-$J12)/W12 -> 0.7355014 | AB12: =IF(Y12>0.5,Y12,0.5) -> 0.56306754 | AC12: 0.56306754 | AE12: =J12/(1-AC12) -> 219.14297 | AF12: 0.24 | AG12: =AE12/(1-AF12) -> 288.34602 | AH12: =AG12/G12 -> 65.454545 | AJ12: =($AG12-Q12)/Q12 -> -0.60899522 | AK12: =($AG12-R12)/R12 -> 0 | AL12: =($AG12-S12)/S12 -> -0.39464649 | AN12: =AE12-J12 -> 123.39229 | AO12: =AN12/G12 -> 28.010051
A13: Ostión | C13: =_xlfn.TEXTJOIN("-",1,A13,E13) -> Ostión-0.414 | D13: Salsa de Ostión 414 ml | E13: 0.414 | F13: =ROUND(1000/G13,0) -> 2073 | G13: =E13*H13 -> 0.48248374 | H13: 1.1654197 | I13: 36682 | J13: =I13/F13 -> 17.695128 | K13: =J13/G13 -> 36.675076 | M13: =_xlfn.MAXIFS('P-0403 - Ostion'!$H:$H,'P-0403 - Ostion'!$I:$I,$E13) -> 508 | N13: =_xlfn.MINIFS('P-0403 - Ostion'!$H:$H,'P-0403 - Ostion'!$I:$I,$E13) -> 112.29167 | O13: =AVERAGEIF('P-0403 - Ostion'!$I:$I,$E13,'P-0403 - Ostion'!$H:$H) -> 236.53138 | Q13: =M13*$G13 -> 245.10174 | R13: =N13*$G13 -> 54.178904 | S13: =O13*$G13 -> 114.12255 | U13: =Q13*0.76 -> 186.27732 | V13: =R13*0.76 -> 41.175967 | W13: =S13*0.76 -> 86.733136 | X13: =(U13-$J13)/U13 -> 0.90500654 | Y13: =(V13-$J13)/V13 -> 0.57025592 | Z13: =(W13-$J13)/W13 -> 0.79598192 | AB13: =IF(Y13>0.5,Y13,0.5) -> 0.57025592 | AC13: 0.57025592 | AE13: =J13/(1-AC13) -> 41.175967 | AF13: 0.24 | AG13: =AE13/(1-AF13) -> 54.178904 | AH13: =AG13/G13 -> 112.29167 | AJ13: =($AG13-Q13)/Q13 -> -0.77895341 | AK13: =($AG13-R13)/R13 -> 1.3114749e-16 | AL13: =($AG13-S13)/S13 -> -0.5252568 | AN13: =AE13-J13 -> 23.480839 | AO13: =AN13/G13 -> 48.666591
A14: Ostión | C14: =_xlfn.TEXTJOIN("-",1,A14,E14) -> Ostión-0.946 | D14: Salsa de Ostión 946 ml | E14: 0.946 | F14: =ROUND(1000/G14,0) -> 907 | G14: =E14*H14 -> 1.102487 | H14: 1.1654197 | I14: 28326 | J14: =I14/F14 -> 31.23043 | K14: =J14/G14 -> 28.327254 | M14: =_xlfn.MAXIFS('P-0403 - Ostion'!$H:$H,'P-0403 - Ostion'!$I:$I,$E14) -> 95.649351 | N14: =_xlfn.MINIFS('P-0403 - Ostion'!$H:$H,'P-0403 - Ostion'!$I:$I,$E14) -> 95.649351 | O14: =AVERAGEIF('P-0403 - Ostion'!$I:$I,$E14,'P-0403 - Ostion'!$H:$H) -> 95.649351 | Q14: =M14*$G14 -> 105.45217 | R14: =N14*$G14 -> 105.45217 | S14: =O14*$G14 -> 105.45217 | U14: =Q14*0.76 -> 80.143646 | V14: =R14*0.76 -> 80.143646 | W14: =S14*0.76 -> 80.143646 | X14: =(U14-$J14)/U14 -> 0.61031933 | Y14: =(V14-$J14)/V14 -> 0.61031933 | Z14: =(W14-$J14)/W14 -> 0.61031933 | AB14: =IF(Y14>0.5,Y14,0.5) -> 0.61031933 | AC14: 0.61031933 | AE14: =J14/(1-AC14) -> 80.143646 | AF14: 0.24 | AG14: =AE14/(1-AF14) -> 105.45217 | AH14: =AG14/G14 -> 95.649351 | AJ14: =($AG14-Q14)/Q14 -> 0 | AK14: =($AG14-R14)/R14 -> 0 | AL14: =($AG14-S14)/S14 -> 0 | AN14: =AE14-J14 -> 48.913216 | AO14: =AN14/G14 -> 44.366252
A15: Mayo Chipotle | B15: BOM-P-0408-001 | C15: =_xlfn.TEXTJOIN("-",1,A15,E15) -> Mayo Chipotle-3.78 | D15: (R&D) Aderezo mayo chipotle 3.8 L (PROJ-0291) | E15: 3.78 | F15: 243 | G15: =E15*H15 -> 4.1152263 | H15: 1.0886842 | I15: 22336.544 | J15: =I15/F15 -> 91.919933 | K15: =J15/G15 -> 22.336544 | M15: =_xlfn.MAXIFS('P-0408 Mayo Chipotle'!$H:$H,'P-0408 Mayo Chipotle'!$I:$I,$E15) -> 112.5 | N15: =_xlfn.MINIFS('P-0408 Mayo Chipotle'!$H:$H,'P-0408 Mayo Chipotle'!$I:$I,$E15) -> 78.684211 | O15: =AVERAGEIF('P-0408 Mayo Chipotle'!$I:$I,$E15,'P-0408 Mayo Chipotle'!$H:$H) -> 95.592105 | Q15: =M15*$G15 -> 462.96296 | R15: =N15*$G15 -> 323.80334 | S15: =O15*$G15 -> 393.38315 | U15: =Q15*0.76 -> 351.85185 | V15: =R15*0.76 -> 246.09053 | W15: =S15*0.76 -> 298.97119 | X15: =(U15-$J15)/U15 -> 0.73875387 | Y15: =(V15-$J15)/V15 -> 0.6264792 | Z15: =(W15-$J15)/W15 -> 0.69254585 | AB15: =IF(Y15>0.5,Y15,0.5) -> 0.6264792 | AC15: 0.55 | AE15: =J15/(1-AC15) -> 204.26652 | AF15: 0.24 | AG15: =AE15/(1-AF15) -> 268.77173 | AH15: =AG15/G15 -> 65.311531 | AJ15: =($AG15-Q15)/Q15 -> -0.41945306 | AK15: =($AG15-R15)/R15 -> -0.16995378 | AL15: =($AG15-S15)/S15 -> -0.31676856 | AN15: =AE15-J15 -> 112.34658 | AO15: =AN15/G15 -> 27.30022
A16: Mayo Chipotle | C16: =_xlfn.TEXTJOIN("-",1,A16,E16) -> Mayo Chipotle-0.946 | D16: Aderezo Mayo Chipotle 946 ml | E16: 0.946 | F16: =ROUND(1000/G16,0) -> 971 | G16: =E16*H16 -> 1.0298953 | H16: 1.0886842 | I16: 29529 | J16: =I16/F16 -> 30.410917 | K16: =J16/G16 -> 29.528164 | M16: =_xlfn.MAXIFS('P-0408 Mayo Chipotle'!$H:$H,'P-0408 Mayo Chipotle'!$I:$I,$E16) -> 0 | N16: =_xlfn.MINIFS('P-0408 Mayo Chipotle'!$H:$H,'P-0408 Mayo Chipotle'!$I:$I,$E16) -> 0 | O16: =IFERROR(AVERAGEIF('P-0408 Mayo Chipotle'!$I:$I,$E16,'P-0408 Mayo Chipotle'!$H:$H),0) -> 0 | Q16: =M16*$G16 -> 0 | R16: =N16*$G16 -> 0 | S16: =O16*$G16 -> 0 | U16: =Q16*0.76 -> 0 | V16: =R16*0.76 -> 0 | W16: =S16*0.76 -> 0 | X16: =IFERROR((U16-$J16)/U16,0) -> 0 | Y16: =IFERROR((V16-$J16)/V16,0) -> 0 | Z16: =IFERROR((W16-$J16)/W16,0) -> 0 | AB16: =IF(Y16>0.5,Y16,0.5) -> 0.5 | AC16: 0.5 | AE16: =J16/(1-AC16) -> 60.821833 | AF16: 0.24 | AG16: =AE16/(1-AF16) -> 80.028728 | AH16: =AG16/G16 -> 77.705695 | AJ16: =($AG16-Q16)/Q16 -> #DIV/0! | AK16: =($AG16-R16)/R16 -> #DIV/0! | AL16: =($AG16-S16)/S16 -> #DIV/0! | AN16: =AE16-J16 -> 30.410917 | AO16: =AN16/G16 -> 29.528164
A17: Mayo Chipotle | C17: =_xlfn.TEXTJOIN("-",1,A17,E17) -> Mayo Chipotle-0.414 | D17: Aderezo Mayo Chipotle 414 ml | E17: 0.414 | F17: =ROUND(1000/G17,0) -> 2219 | G17: =E17*H17 -> 0.45071527 | H17: 1.0886842 | I17: 38396 | J17: =I17/F17 -> 17.30329 | K17: =J17/G17 -> 38.390734 | M17: =_xlfn.MAXIFS('P-0408 Mayo Chipotle'!$H:$H,'P-0408 Mayo Chipotle'!$I:$I,$E17) -> 166.66667 | N17: =_xlfn.MINIFS('P-0408 Mayo Chipotle'!$H:$H,'P-0408 Mayo Chipotle'!$I:$I,$E17) -> 96.470588 | O17: =AVERAGEIF('P-0408 Mayo Chipotle'!$I:$I,$E17,'P-0408 Mayo Chipotle'!$H:$H) -> 126.51018 | Q17: =M17*$G17 -> 75.119211 | R17: =N17*$G17 -> 43.480767 | S17: =O17*$G17 -> 57.020069 | U17: =Q17*0.76 -> 57.0906 | V17: =R17*0.76 -> 33.045383 | W17: =S17*0.76 -> 43.335252 | X17: =(U17-$J17)/U17 -> 0.69691526 | Y17: =(V17-$J17)/V17 -> 0.47637799 | Z17: =(W17-$J17)/W17 -> 0.600711 | AB17: =IF(Y17>0.5,Y17,0.5) -> 0.5 | AC17: 0.5 | AE17: =J17/(1-AC17) -> 34.60658 | AF17: 0.24 | AG17: =AE17/(1-AF17) -> 45.534973 | AH17: =AG17/G17 -> 101.02825 | AJ17: =($AG17-Q17)/Q17 -> -0.39383052 | AK17: =($AG17-R17)/R17 -> 0.047244022 | AL17: =($AG17-S17)/S17 -> -0.20142199 | AN17: =AE17-J17 -> 17.30329 | AO17: =AN17/G17 -> 38.390734

Sheet P-0403 - Ostion
A1: Serie | B1: Marca | C1: canal | D1: vendedor | E1: presentacion | F1: precio | G1: Ventas | H1: costo/kg | I1: Referencia
A2: Competencia | B2: Lee kum kee | C2: Amazon | D2: Ranita de la paz | E2: 2.2 | F2: 209 | H2: =F2/E2 -> 95 | I2: 3.78
A3: Competencia | B3: Lee kum kee | C3: HEB | E3: 2.27 | F3: 244 | H3: =F3/E3 -> 107.48899 | I3: 3.78
A4: Competencia | B4: Lee kum kee | C4: HEB | E4: 0.48 | F4: 66.9 | H4: =F4/E4 -> 139.375 | I4: 0.414
A5: Competencia | B5: Maatsuri | C5: HEB | E5: 0.42 | F5: 63.9 | H5: =F5/E5 -> 152.14286 | I5: 0.414
A6: Competencia | B6: Lee kum kee | C6: HEB | E6: 0.51 | F6: 135 | H6: =F6/E6 -> 264.70588 | I6: 0.414
A7: Competencia | B7: Thai pride | C7: HEB | E7: 0.295 | F7: 47 | H7: =F7/E7 -> 159.32203 | I7: 0.414
A8: Competencia | B8: Polar | C8: HEB | E8: 0.15 | F8: 68 | H8: =F8/E8 -> 453.33333 | I8: 0.414
A9: Competencia | B9: Thai prestige | C9: HEB | E9: 0.32 | F9: 54 | H9: =F9/E9 -> 168.75 | I9: 0.414
A10: Competencia | B10: Haday | C10: ML | D10: Yang foods | E10: 2.27 | F10: 239 | G10: 100 | H10: =F10/E10 -> 105.28634 | I10: 3.78
A11: Competencia | B11: Kikoman | C11: ML | D11: Tienda Obachan | E11: 2.27 | F11: 380 | G11: 100 | H11: =F11/E11 -> 167.40088 | I11: 3.78
A12: Competencia | B12: Lee kum kee | C12: ML | D12: Toyo foods | E12: 2.2 | F12: 144 | G12: 10000 | H12: =F12/E12 -> 65.454545 | I12: 3.78
A13: Competencia | B13: Thaui prestige | C13: Sams | E13: 0.77 | F13: 73.65 | H13: =F13/E13 -> 95.649351 | I13: 0.946
A14: Competencia | B14: Uteki | C14: Walmart | E14: 0.27 | F14: 40 | H14: =F14/E14 -> 148.14815 | I14: 0.414
A15: Competencia | B15: Unkai | C15: Walmart | E15: 0.25 | F15: 127 | H15: =F15/E15 -> 508 | I15: 0.414
A16: Competencia | C16: Zorro Abarrotero
A17: Competencia | B17: NA | C17: Scorpion | D17: NA | G17: NA
A18: Competencia | B18: Thaui prestige | C18: Chedraui | D18: Chedraui | E18: 0.32 | F18: 56 | H18: =F18/E18 -> 175 | I18: 0.414
A19: Competencia | B19: Yumart | C19: Chedraui | D19: Yumart | E19: 0.26 | F19: 60 | H19: =F19/E19 -> 230.76923 | I19: 0.414
A20: Competencia | B20: Kum Chun | C20: Smart n final | D20: Smart n final | E20: 0.48 | F20: 53.9 | H20: =F20/E20 -> 112.29167 | I20: 0.414
A21: Competencia | B21: Mitsuki | C21: Smart n final | D21: Smart n final | E21: 0.26 | F21: 84.9 | H21: =F21/E21 -> 326.53846 | I21: 0.414
A22: Competencia | B22: NA | C22: Costco
A23: Competencia | B23: NA | C23: APYS
A24: Takumi-Ichi | B24: Ostión-3.78 | E24: 3.78 | F24: =VLOOKUP(B24,'260324 costeo'!C:AG,31,0) -> 288.34602 | H24: =F24/E24 -> 76.282015
A25: Takumi-Ichi | B25: Ostión-0.414 | E25: 0.414 | F25: =VLOOKUP(B25,'260324 costeo'!C:AG,31,0) -> 54.178904 | H25: =F25/E25 -> 130.86692
A26: Takumi-Ichi | B26: Ostión-0.946 | E26: 0.946 | F26: =VLOOKUP(B26,'260324 costeo'!C:AG,31,0) -> 105.45217 | H26: =F26/E26 -> 111.47163

Sheet P-0404 Teriyaki
A1: Serie | B1: Marca | C1: canal | D1: vendedor | E1: presentacion | F1: precio | G1: Ventas | H1: costo/kg | I1: Referencia
A2: Competencia | B2: Thai prestige | C2: Chedraui | D2: Chedraui | E2: 0.32 | F2: 59 | H2: =F2/E2 -> 184.375 | I2: 0.414
A3: Competencia | B3: Kikkoman | C3: Chedraui | D3: Chedraui | E3: 0.34 | F3: 81 | H3: =F3/E3 -> 238.23529 | I3: 0.414
A4: Competencia | B4: Keemaki | C4: Chedraui | D4: Chedraui | E4: 0.355 | F4: 47 | H4: =F4/E4 -> 132.39437 | I4: 0.414
A5: Competencia | B5: Blue dragon | C5: Chedraui | D5: Chedraui | E5: 0.19 | F5: 87 | H5: =F5/E5 -> 457.89474 | I5: 0.414
A6: Competencia | B6: Umami tokyo | C6: Chedraui | D6: Chedraui | E6: 0.25 | F6: 29 | H6: =F6/E6 -> 116 | I6: 0.414
A7: Competencia | B7: Paanda Express | C7: Chedraui | D7: Chedraui | E7: 0.581 | F7: 139 | H7: =F7/E7 -> 239.24269 | I7: 0.414
A8: Competencia | B8: Lee kum kee | C8: Chedraui | D8: Chedraui | E8: 0.25 | F8: 135 | H8: =F8/E8 -> 540 | I8: 0.414
A9: Competencia | B9: Unkai | C9: Chedraui | D9: Chedraui | E9: 0.3 | F9: 65 | H9: =F9/E9 -> 216.66667 | I9: 0.414
A10: Competencia | B10: Kinders | C10: Chedraui | D10: Chedraui | E10: 0.448 | F10: 99 | H10: =F10/E10 -> 220.98214 | I10: 0.414
A11: Competencia | B11: Subway | C11: Chedraui | D11: Chedraui | E11: 0.473 | F11: 102 | H11: =F11/E11 -> 215.64482 | I11: 0.414
A12: Competencia | B12: Kikkoman | C12: Smart n final | D12: Smart n final | E12: 0.34 | F12: 91.5 | H12: =F12/E12 -> 269.11765 | I12: 0.414
A13: Competencia | B13: Lee kum kee | C13: Smart n final | D13: Smart n final | E13: 0.227 | F13: 38.9 | H13: =F13/E13 -> 171.36564 | I13: 0.414
A14: Competencia | B14: Kikkoman | C14: HEB | E14: 0.34 | F14: 103 | H14: =F14/E14 -> 302.94118 | I14: 0.414
A15: Competencia | B15: Kikkoman | C15: HEB | E15: 0.296 | F15: 93 | H15: =F15/E15 -> 314.18919 | I15: 0.414
A16: Competencia | B16: Kaporo | C16: HEB | E16: 0.35 | F16: 41 | H16: =F16/E16 -> 117.14286 | I16: 0.414
A17: Competencia | B17: House of tsang | C17: HEB | E17: 0.326 | F17: 121 | H17: =F17/E17 -> 371.16564 | I17: 0.414
A18: Competencia | B18: HEB | C18: HEB | E18: 0.355 | F18: 62.9 | H18: =F18/E18 -> 177.1831 | I18: 0.414
A19: Competencia | B19: Lee kum kee | C19: HEB | E19: 0.25 | F19: 135 | H19: =F19/E19 -> 540 | I19: 0.414
A20: Competencia | B20: Kaporo | C20: Walmart | E20: 0.35 | F20: 39 | H20: =F20/E20 -> 111.42857 | I20: 0.414
A21: Competencia | B21: Great value | C21: Walmart | E21: 0.444 | F21: 50 | H21: =F21/E21 -> 112.61261 | I21: 0.414
A22: Competencia | B22: Kikkoman | C22: Walmart | E22: 0.296 | F22: 80 | H22: =F22/E22 -> 270.27027 | I22: 0.414
A23: Competencia | B23: Kikkoman | C23: Walmart | E23: 0.34 | F23: 76 | H23: =F23/E23 -> 223.52941 | I23: 0.414
A24: Competencia | B24: Kikkoman | C24: ML | D24: Toyo foods | E24: 2.27 | F24: 330 | G24: 500 | H24: =F24/E24 -> 145.37445 | I24: 3.78
A25: Competencia | B25: Kikkoman | C25: Amazon | D25: Toyo foods | E25: 2.27 | F25: 427 | H25: =F25/E25 -> 188.10573 | I25: 3.78
A26: Mr Wings | B26: Mr Wings | C26: APYS | D26: APYS | E26: 3.8 | F26: 261 | H26: =F26/E26 -> 68.684211 | I26: 3.78
A27: Competencia | B27: Ventura | C27: APYS | D27: APYS | E27: 3.8 | F27: 462 | H27: =F27/E27 -> 121.57895 | I27: 3.78
A28: Competencia | B28: NA | C28: Sams
A29: Competencia | C29: Zorro Abarrotero
A30: Competencia | C30: Scorpion
A31: Competencia | B31: NA | C31: Costco | D31: NA
A32: Competencia | C32: Amazon
A33: Takumi Ichi | B33: Teriyaki-3.78 | E33: 3.78 | F33: =VLOOKUP(B33,'260324 costeo'!C:AG,31,0) -> 323.98213 | H33: =F33/E33 -> 85.709557
A34: Takumi Ichi | B34: Teriyaki-0.946 | E34: 0.946 | F34: =VLOOKUP(B34,'260324 costeo'!C:AG,31,0) -> 88.007208 | H34: =F34/E34 -> 93.030875
A35: Takumi Ichi | B35: Teriyaki-0.414 | E35: 0.414 | F35: =VLOOKUP(B35,'260324 costeo'!C:AG,31,0) -> 57.566423 | H35: =F35/E35 -> 139.04933

Sheet P-0408 Mayo Chipotle
A1: Serie | B1: Marca | C1: canal | D1: vendedor | E1: presentacion | F1: precio | G1: Ventas | H1: costo/kg | I1: Referencia
A2: Competencia | B2: Mccormick | C2: ML | D2: Mccormick | E2: 0.31 | F2: 32 | G2: 1000 | H2: =F2/E2 -> 103.22581 | I2: 0.414
A3: Competencia | B3: Zaaschila | C3: Walmart | D3: Walmart | E3: 0.425 | F3: 41 | H3: =F3/E3 -> 96.470588 | I3: 0.414
A4: Competencia | B4: Hellmanns | C4: Walmart | D4: Walmart | E4: 0.31 | F4: 41 | H4: =F4/E4 -> 132.25806 | I4: 0.414
A5: Competencia | B5: Mccormick | C5: Walmart | D5: Walmart | E5: 0.31 | F5: 36 | H5: =F5/E5 -> 116.12903 | I5: 0.414
